Workbook

Sheet 月次まとめ
A1: 2026年7月 仕上操業 月次まとめ
A2: 各セクション月次集計シートへのリンクと、月間の主要KPI（数式で自動集計）。
A4: セクション別シート
A5: （１）５C/Rワインダー
A6: （２）５C/Rカッター・平包
A7: （３）仕上２Ｇ
A8: （４）生産高
A9: （５）損紙発生量合計
A12: 月間KPI
A13: 指標 | B13: 値
A14: 5C/Rワインダー 月間処理量合計(t) | B14: =SUM(5CRワインダー_月次!D4:D34) -> 12493.848
A15: 5C/Rカッター 月間処理量合計(t) | B15: =SUM(5CRカッター平包_月次!E4:E34) -> 4544.3
A16: 5C/R平包 月間合計(t) | B16: =SUM(5CRカッター平包_月次!O4:O34) -> 3707
A17: 既設カッター 月間処理量合計(t) | B17: =SUM(生産高_月次!B4:B34) -> 2419.587
A18: 仕上２Ｇ 平均「下」比率(%) | B18: =AVERAGE(仕上2G_月次!D4:D34) -> 6.5330605
A19: 仕上２Ｇ 月間損紙発生量合計 | B19: =SUM(仕上2G_月次!I4:I34) -> 286
A20: 5CR 発生損紙 月間合計(kg) | B20: =SUM(損紙発生量合計_月次!F4:F34) -> 749983
A21: 既設 発生損紙 月間合計(kg) | B21: =SUM(損紙発生量合計_月次!J4:J34) -> 161501
A22: 5CRワインダー 月間損紙合計(kg) | B22: =SUM(5CRワインダー_月次!G4:G34) -> 578383
A23: 5CRワインダー 処理本数合計(本) | B23: =SUM(5CRワインダー_月次!F4:F34) -> 656
A24: パルパー移送量 月間合計(kg) | B24: =SUM(5CRカッター平包_月次!G4:G34) -> 796200

Sheet 5CRワインダー_月次
A1: （１）５C/Rワインダー 月次集計
A2: データ出典: 各日シート（1日～31日）へのリンク数式。数値は元シートの値がそのまま反映されます。
A3: 日 | B3: #1処理量(t) | C3: #2処理量(t) | D3: 合計処理量(t) | E3: 合計累計(t) | F3: ワインダー処理本数(本) | G3: 損紙(kg) | H3: 巻取累計(kg) | I3: 欠陥J(本) | J3: 欠陥P(本) | K3: 欠陥S(本) | L3: 停止時間(hr) | M3: 製品待ち時間(hr)
A4: 1日 | B4: =IFERROR(1日!D4,"") -> 198.953 | C4: =IFERROR(1日!D9,"") -> 179.365 | D4: =IFERROR(1日!D14,"") -> 378.318 | E4: =IFERROR(1日!G14,"") -> 378.318 | F4: =IFERROR(1日!Q19,"") -> 25 | G4: =IFERROR(1日!P14,"") -> 34237 | H4: =IFERROR(1日!W14,"") -> 34237 | I4: =IFERROR(1日!AB19,"") -> 0 | J4: =IFERROR(1日!AF19,"") -> 12 | K4: =IFERROR(1日!AJ19,"") -> 2 | L4: =IFERROR(1日!AO4*24,"") -> 1.3333333 | M4: =IFERROR(1日!AR4*24,"") -> 0
A5: 2日 | B5: =IFERROR(2日!D4,"") -> 203.546 | C5: =IFERROR(2日!D9,"") -> 209.281 | D5: =IFERROR(2日!D14,"") -> 412.827 | E5: =IFERROR(2日!G14,"") -> 791.145 | F5: =IFERROR(2日!Q19,"") -> 26 | G5: =IFERROR(2日!P14,"") -> 8051 | H5: =IFERROR(2日!W14,"") -> 42288 | I5: =IFERROR(2日!AB19,"") -> 3 | J5: =IFERROR(2日!AF19,"") -> 18 | K5: =IFERROR(2日!AJ19,"") -> 2 | L5: =IFERROR(2日!AO4*24,"") -> 1.9166667 | M5: =IFERROR(2日!AR4*24,"") -> 0
A6: 3日 | B6: =IFERROR(3日!D4,"") -> 192.598 | C6: =IFERROR(3日!D9,"") -> 190.514 | D6: =IFERROR(3日!D14,"") -> 383.112 | E6: =IFERROR(3日!G14,"") -> 1174.257 | F6: =IFERROR(3日!Q19,"") -> 23 | G6: =IFERROR(3日!P14,"") -> 1745 | H6: =IFERROR(3日!W14,"") -> 44033 | I6: =IFERROR(3日!AB19,"") -> 1 | J6: =IFERROR(3日!AF19,"") -> 10 | K6: =IFERROR(3日!AJ19,"") -> 5 | L6: =IFERROR(3日!AO4*24,"") -> 1.6666667 | M6: =IFERROR(3日!AR4*24,"") -> 0
A7: 4日 | B7: =IFERROR(4日!D4,"") -> 187.883 | C7: =IFERROR(4日!D9,"") -> 197.308 | D7: =IFERROR(4日!D14,"") -> 385.191 | E7: =IFERROR(4日!G14,"") -> 1559.448 | F7: =IFERROR(4日!Q19,"") -> 23 | G7: =IFERROR(4日!P14,"") -> 1039 | H7: =IFERROR(4日!W14,"") -> 45072 | I7: =IFERROR(4日!AB19,"") -> 1 | J7: =IFERROR(4日!AF19,"") -> 9 | K7: =IFERROR(4日!AJ19,"") -> 1 | L7: =IFERROR(4日!AO4*24,"") -> 2 | M7: =IFERROR(4日!AR4*24,"") -> 1.8333333
A8: 5日 | B8: =IFERROR(5日!D4,"") -> 198.932 | C8: =IFERROR(5日!D9,"") -> 202.384 | D8: =IFERROR(5日!D14,"") -> 401.316 | E8: =IFERROR(5日!G14,"") -> 1960.764 | F8: =IFERROR(5日!Q19,"") -> 26 | G8: =IFERROR(5日!P14,"") -> 2680 | H8: =IFERROR(5日!W14,"") -> 47752 | I8: =IFERROR(5日!AB19,"") -> 0 | J8: =IFERROR(5日!AF19,"") -> 30 | K8: =IFERROR(5日!AJ19,"") -> 2 | L8: =IFERROR(5日!AO4*24,"") -> 1 | M8: =IFERROR(5日!AR4*24,"") -> 0
A9: 6日 | B9: =IFERROR(6日!D4,"") -> 184.832 | C9: =IFERROR(6日!D9,"") -> 176.136 | D9: =IFERROR(6日!D14,"") -> 360.968 | E9: =IFERROR(6日!G14,"") -> 2321.732 | F9: =IFERROR(6日!Q19,"") -> 18 | G9: =IFERROR(6日!P14,"") -> 16802 | H9: =IFERROR(6日!W14,"") -> 64554 | I9: =IFERROR(6日!AB19,"") -> 0 | J9: =IFERROR(6日!AF19,"") -> 27 | K9: =IFERROR(6日!AJ19,"") -> 1 | L9: =IFERROR(6日!AO4*24,"") -> 2 | M9: =IFERROR(6日!AR4*24,"") -> 0
A10: 7日 | B10: =IFERROR(7日!D4,"") -> 169.607 | C10: =IFERROR(7日!D9,"") -> 190.811 | D10: =IFERROR(7日!D14,"") -> 360.418 | E10: =IFERROR(7日!G14,"") -> 2682.15 | F10: =IFERROR(7日!Q19,"") -> 18 | G10: =IFERROR(7日!P14,"") -> 14376 | H10: =IFERROR(7日!W14,"") -> 78930 | I10: =IFERROR(7日!AB19,"") -> 1 | J10: =IFERROR(7日!AF19,"") -> 6 | K10: =IFERROR(7日!AJ19,"") -> 0 | L10: =IFERROR(7日!AO4*24,"") -> 1.3333333 | M10: =IFERROR(7日!AR4*24,"") -> 0
A11: 8日 | B11: =IFERROR(8日!D4,"") -> 236.645 | C11: =IFERROR(8日!D9,"") -> 215.639 | D11: =IFERROR(8日!D14,"") -> 452.284 | E11: =IFERROR(8日!G14,"") -> 3134.434 | F11: =IFERROR(8日!Q19,"") -> 20 | G11: =IFERROR(8日!P14,"") -> 14101 | H11: =IFERROR(8日!W14,"") -> 93031 | I11: =IFERROR(8日!AB19,"") -> 1 | J11: =IFERROR(8日!AF19,"") -> 16 | K11: =IFERROR(8日!AJ19,"") -> 1 | L11: =IFERROR(8日!AO4*24,"") -> 0.66666667 | M11: =IFERROR(8日!AR4*24,"") -> 0
A12: 9日 | B12: =IFERROR(9日!D4,"") -> 239.286 | C12: =IFERROR(9日!D9,"") -> 225.038 | D12: =IFERROR(9日!D14,"") -> 464.324 | E12: =IFERROR(9日!G14,"") -> 3598.758 | F12: =IFERROR(9日!Q19,"") -> 20 | G12: =IFERROR(9日!P14,"") -> 17057 | H12: =IFERROR(9日!W14,"") -> 110088 | I12: =IFERROR(9日!AB19,"") -> 0 | J12: =IFERROR(9日!AF19,"") -> 15 | K12: =IFERROR(9日!AJ19,"") -> 1 | L12: =IFERROR(9日!AO4*24,"") -> 0.66666667 | M12: =IFERROR(9日!AR4*24,"") -> 0
A13: 10日 | B13: =IFERROR(10日!D4,"") -> 196.614 | C13: =IFERROR(10日!D9,"") -> 239.704 | D13: =IFERROR(10日!D14,"") -> 436.318 | E13: =IFERROR(10日!G14,"") -> 4035.076 | F13: =IFERROR(10日!Q19,"") -> 18 | G13: =IFERROR(10日!P14,"") -> 15506 | H13: =IFERROR(10日!W14,"") -> 125594 | I13: =IFERROR(10日!AB19,"") -> 0 | J13: =IFERROR(10日!AF19,"") -> 12 | K13: =IFERROR(10日!AJ19,"") -> 0 | L13: =IFERROR(10日!AO4*24,"") -> 1.3333333 | M13: =IFERROR(10日!AR4*24,"") -> 1.1666667
A14: 11日 | B14: =IFERROR(11日!D4,"") -> 148.346 | C14: =IFERROR(11日!D9,"") -> 236.39 | D14: =IFERROR(11日!D14,"") -> 384.736 | E14: =IFERROR(11日!G14,"") -> 4419.812 | F14: =IFERROR(11日!Q19,"") -> 21 | G14: =IFERROR(11日!P14,"") -> 5494 | H14: =IFERROR(11日!W14,"") -> 131088 | I14: =IFERROR(11日!AB19,"") -> 0 | J14: =IFERROR(11日!AF19,"") -> 11 | K14: =IFERROR(11日!AJ19,"") -> 1 | L14: =IFERROR(11日!AO4*24,"") -> 0 | M14: =IFERROR(11日!AR4*24,"") -> 0
A15: 12日 | B15: =IFERROR(12日!D4,"") -> 251.54 | C15: =IFERROR(12日!D9,"") -> 277.04 | D15: =IFERROR(12日!D14,"") -> 528.58 | E15: =IFERROR(12日!G14,"") -> 4948.392 | F15: =IFERROR(12日!Q19,"") -> 25 | G15: =IFERROR(12日!P14,"") -> 17446 | H15: =IFERROR(12日!W14,"") -> 148534 | I15: =IFERROR(12日!AB19,"") -> 0 | J15: =IFERROR(12日!AF19,"") -> 17 | K15: =IFERROR(12日!AJ19,"") -> 0 | L15: =IFERROR(12日!AO4*24,"") -> 0 | M15: =IFERROR(12日!AR4*24,"") -> 0
A16: 13日 | B16: =IFERROR(13日!D4,"") -> 215.529 | C16: =IFERROR(13日!D9,"") -> 244.092 | D16: =IFERROR(13日!D14,"") -> 459.621 | E16: =IFERROR(13日!G14,"") -> 5408.013 | F16: =IFERROR(13日!Q19,"") -> 24 | G16: =IFERROR(13日!P14,"") -> 15217 | H16: =IFERROR(13日!W14,"") -> 163751 | I16: =IFERROR(13日!AB19,"") -> 1 | J16: =IFERROR(13日!AF19,"") -> 6 | K16: =IFERROR(13日!AJ19,"") -> 0 | L16: =IFERROR(13日!AO4*24,"") -> 2.3333333 | M16: =IFERROR(13日!AR4*24,"") -> 0
A17: 14日 | B17: =IFERROR(14日!D4,"") -> 179.224 | C17: =IFERROR(14日!D9,"") -> 218.83 | D17: =IFERROR(14日!D14,"") -> 398.054 | E17: =IFERROR(14日!G14,"") -> 5806.067 | F17: =IFERROR(14日!Q19,"") -> 23 | G17: =IFERROR(14日!P14,"") -> 27999 | H17: =IFERROR(14日!W14,"") -> 191750 | I17: =IFERROR(14日!AB19,"") -> 0 | J17: =IFERROR(14日!AF19,"") -> 8 | K17: =IFERROR(14日!AJ19,"") -> 1 | L17: =IFERROR(14日!AO4*24,"") -> 1.6666667 | M17: =IFERROR(14日!AR4*24,"") -> 0
A18: 15日 | B18: =IFERROR(15日!D4,"") -> 163.562 | C18: =IFERROR(15日!D9,"") -> 148.229 | D18: =IFERROR(15日!D14,"") -> 311.791 | E18: =IFERROR(15日!G14,"") -> 6117.858 | F18: =IFERROR(15日!Q19,"") -> 19 | G18: =IFERROR(15日!P14,"") -> 5534 | H18: =IFERROR(15日!W14,"") -> 197284 | I18: =IFERROR(15日!AB19,"") -> 0 | J18: =IFERROR(15日!AF19,"") -> 8 | K18: =IFERROR(15日!AJ19,"") -> 0 | L18: =IFERROR(15日!AO4*24,"") -> 0.33333333 | M18: =IFERROR(15日!AR4*24,"") -> 0
A19: 16日 | B19: =IFERROR(16日!D4,"") -> 174.813 | C19: =IFERROR(16日!D9,"") -> 186.502 | D19: =IFERROR(16日!D14,"") -> 361.315 | E19: =IFERROR(16日!G14,"") -> 6479.173 | F19: =IFERROR(16日!Q19,"") -> 20 | G19: =IFERROR(16日!P14,"") -> 25828 | H19: =IFERROR(16日!W14,"") -> 223112 | I19: =IFERROR(16日!AB19,"") -> 0 | J19: =IFERROR(16日!AF19,"") -> 17 | K19: =IFERROR(16日!AJ19,"") -> 3 | L19: =IFERROR(16日!AO4*24,"") -> 1 | M19: =IFERROR(16日!AR4*24,"") -> 0
A20: 17日 | B20: =IFERROR(17日!D4,"") -> 165.369 | C20: =IFERROR(17日!D9,"") -> 151.061 | D20: =IFERROR(17日!D14,"") -> 316.43 | E20: =IFERROR(17日!G14,"") -> 6795.603 | F20: =IFERROR(17日!Q19,"") -> 15 | G20: =IFERROR(17日!P14,"") -> 21460 | H20: =IFERROR(17日!W14,"") -> 244572 | I20: =IFERROR(17日!AB19,"") -> 0 | J20: =IFERROR(17日!AF19,"") -> 16 | K20: =IFERROR(17日!AJ19,"") -> 4 | L20: =IFERROR(17日!AO4*24,"") -> 2.6666667 | M20: =IFERROR(17日!AR4*24,"") -> 0
A21: 18日 | B21: =IFERROR(18日!D4,"") -> 178.923 | C21: =IFERROR(18日!D9,"") -> 243.75 | D21: =IFERROR(18日!D14,"") -> 422.673 | E21: =IFERROR(18日!G14,"") -> 7218.276 | F21: =IFERROR(18日!Q19,"") -> 23 | G21: =IFERROR(18日!P14,"") -> 21784 | H21: =IFERROR(18日!W14,"") -> 266356 | I21: =IFERROR(18日!AB19,"") -> 1 | J21: =IFERROR(18日!AF19,"") -> 13 | K21: =IFERROR(18日!AJ19,"") -> 5 | L21: =IFERROR(18日!AO4*24,"") -> 0.66666667 | M21: =IFERROR(18日!AR4*24,"") -> 0
A22: 19日 | B22: =IFERROR(19日!D4,"") -> 151.73 | C22: =IFERROR(19日!D9,"") -> 173.973 | D22: =IFERROR(19日!D14,"") -> 325.703 | E22: =IFERROR(19日!G14,"") -> 7543.979 | F22: =IFERROR(19日!Q19,"") -> 18 | G22: =IFERROR(19日!P14,"") -> 23338 | H22: =IFERROR(19日!W14,"") -> 289694 | I22: =IFERROR(19日!AB19,"") -> 0 | J22: =IFERROR(19日!AF19,"") -> 9 | K22: =IFERROR(19日!AJ19,"") -> 9 | L22: =IFERROR(19日!AO4*24,"") -> 1 | M22: =IFERROR(19日!AR4*24,"") -> 0
A23: 20日 | B23: =IFERROR(20日!D4,"") -> 241.499 | C23: =IFERROR(20日!D9,"") -> 242.315 | D23: =IFERROR(20日!D14,"") -> 483.814 | E23: =IFERROR(20日!G14,"") -> 8027.793 | F23: =IFERROR(20日!Q19,"") -> 26 | G23: =IFERROR(20日!P14,"") -> 932 | H23: =IFERROR(20日!W14,"") -> 290626 | I23: =IFERROR(20日!AB19,"") -> 0 | J23: =IFERROR(20日!AF19,"") -> 3 | K23: =IFERROR(20日!AJ19,"") -> 1 | L23: =IFERROR(20日!AO4*24,"") -> 0.33333333 | M23: =IFERROR(20日!AR4*24,"") -> 0
A24: 21日 | B24: =IFERROR(21日!D4,"") -> 223.027 | C24: =IFERROR(21日!D9,"") -> 220.484 | D24: =IFERROR(21日!D14,"") -> 443.511 | E24: =IFERROR(21日!G14,"") -> 8471.304 | F24: =IFERROR(21日!Q19,"") -> 24 | G24: =IFERROR(21日!P14,"") -> 12817 | H24: =IFERROR(21日!W14,"") -> 303443 | I24: =IFERROR(21日!AB19,"") -> 0 | J24: =IFERROR(21日!AF19,"") -> 22 | K24: =IFERROR(21日!AJ19,"") -> 1 | L24: =IFERROR(21日!AO4*24,"") -> 0.66666667 | M24: =IFERROR(21日!AR4*24,"") -> 0
A25: 22日 | B25: =IFERROR(22日!D4,"") -> 245.348 | C25: =IFERROR(22日!D9,"") -> 261.423 | D25: =IFERROR(22日!D14,"") -> 506.771 | E25: =IFERROR(22日!G14,"") -> 8978.075 | F25: =IFERROR(22日!Q19,"") -> 24 | G25: =IFERROR(22日!P14,"") -> 16692 | H25: =IFERROR(22日!W14,"") -> 320135 | I25: =IFERROR(22日!AB19,"") -> 0 | J25: =IFERROR(22日!AF19,"") -> 26 | K25: =IFERROR(22日!AJ19,"") -> 0 | L25: =IFERROR(22日!AO4*24,"") -> 0.66666667 | M25: =IFERROR(22日!AR4*24,"") -> 0
A26: 23日 | B26: =IFERROR(23日!D4,"") -> 229.026 | C26: =IFERROR(23日!D9,"") -> 183.557 | D26: =IFERROR(23日!D14,"") -> 412.583 | E26: =IFERROR(23日!G14,"") -> 9390.658 | F26: =IFERROR(23日!Q19,"") -> 21 | G26: =IFERROR(23日!P14,"") -> 8415 | H26: =IFERROR(23日!W14,"") -> 328550 | I26: =IFERROR(23日!AB19,"") -> 2 | J26: =IFERROR(23日!AF19,"") -> 7 | K26: =IFERROR(23日!AJ19,"") -> 0 | L26: =IFERROR(23日!AO4*24,"") -> 0.66666667 | M26: =IFERROR(23日!AR4*24,"") -> 0
A27: 24日 | B27: =IFERROR(24日!D4,"") -> 112.494 | C27: =IFERROR(24日!D9,"") -> 152.809 | D27: =IFERROR(24日!D14,"") -> 265.303 | E27: =IFERROR(24日!G14,"") -> 9655.961 | F27: =IFERROR(24日!Q19,"") -> 15 | G27: =IFERROR(24日!P14,"") -> 42298 | H27: =IFERROR(24日!W14,"") -> 370848 | I27: =IFERROR(24日!AB19,"") -> 4 | J27: =IFERROR(24日!AF19,"") -> 32 | K27: =IFERROR(24日!AJ19,"") -> 2 | L27: =IFERROR(24日!AO4*24,"") -> 1.5833333 | M27: =IFERROR(24日!AR4*24,"") -> 3.5
A28: 25日 | B28: =IFERROR(25日!D4,"") -> 193.41 | C28: =IFERROR(25日!D9,"") -> 199.113 | D28: =IFERROR(25日!D14,"") -> 392.523 | E28: =IFERROR(25日!G14,"") -> 10048.484 | F28: =IFERROR(25日!Q19,"") -> 18 | G28: =IFERROR(25日!P14,"") -> 30496 | H28: =IFERROR(25日!W14,"") -> 401344 | I28: =IFERROR(25日!AB19,"") -> 2 | J28: =IFERROR(25日!AF19,"") -> 45 | K28: =IFERROR(25日!AJ19,"") -> 1 | L28: =IFERROR(25日!AO4*24,"") -> 1.3333333 | M28: =IFERROR(25日!AR4*24,"") -> 0
A29: 26日 | B29: =IFERROR(26日!D4,"") -> 152.437 | C29: =IFERROR(26日!D9,"") -> 186.178 | D29: =IFERROR(26日!D14,"") -> 338.615 | E29: =IFERROR(26日!G14,"") -> 10387.099 | F29: =IFERROR(26日!Q19,"") -> 18 | G29: =IFERROR(26日!P14,"") -> 28180 | H29: =IFERROR(26日!W14,"") -> 429524 | I29: =IFERROR(26日!AB19,"") -> 1 | J29: =IFERROR(26日!AF19,"") -> 10 | K29: =IFERROR(26日!AJ19,"") -> 3 | L29: =IFERROR(26日!AO4*24,"") -> 1.3333333 | M29: =IFERROR(26日!AR4*24,"") -> 0
A30: 27日 | B30: =IFERROR(27日!D4,"") -> 172.818 | C30: =IFERROR(27日!D9,"") -> 192.37 | D30: =IFERROR(27日!D14,"") -> 365.188 | E30: =IFERROR(27日!G14,"") -> 10752.287 | F30: =IFERROR(27日!Q19,"") -> 22 | G30: =IFERROR(27日!P14,"") -> 30992 | H30: =IFERROR(27日!W14,"") -> 460516 | I30: =IFERROR(27日!AB19,"") -> 2 | J30: =IFERROR(27日!AF19,"") -> 10 | K30: =IFERROR(27日!AJ19,"") -> 1 | L30: =IFERROR(27日!AO4*24,"") -> 0.33333333 | M30: =IFERROR(27日!AR4*24,"") -> 0
A31: 28日 | B31: =IFERROR(28日!D4,"") -> 196.017 | C31: =IFERROR(28日!D9,"") -> 193.871 | D31: =IFERROR(28日!D14,"") -> 389.888 | E31: =IFERROR(28日!G14,"") -> 11142.175 | F31: =IFERROR(28日!Q19,"") -> 21 | G31: =IFERROR(28日!P14,"") -> 32250 | H31: =IFERROR(28日!W14,"") -> 492766 | I31: =IFERROR(28日!AB19,"") -> 0 | J31: =IFERROR(28日!AF19,"") -> 16 | K31: =IFERROR(28日!AJ19,"") -> 2 | L31: =IFERROR(28日!AO4*24,"") -> 0.66666667 | M31: =IFERROR(28日!AR4*24,"") -> 0
A32: 29日 | B32: =IFERROR(29日!D4,"") -> 204.662 | C32: =IFERROR(29日!D9,"") -> 246.888 | D32: =IFERROR(29日!D14,"") -> 451.55 | E32: =IFERROR(29日!G14,"") -> 11593.725 | F32: =IFERROR(29日!Q19,"") -> 23 | G32: =IFERROR(29日!P14,"") -> 30454 | H32: =IFERROR(29日!W14,"") -> 523220 | I32: =IFERROR(29日!AB19,"") -> 1 | J32: =IFERROR(29日!AF19,"") -> 11 | K32: =IFERROR(29日!AJ19,"") -> 1 | L32: =IFERROR(29日!AO4*24,"") -> 0.66666667 | M32: =IFERROR(29日!AR4*24,"") -> 0
A33: 30日 | B33: =IFERROR(30日!D4,"") -> 267.632 | C33: =IFERROR(30日!D9,"") -> 251.757 | D33: =IFERROR(30日!D14,"") -> 519.389 | E33: =IFERROR(30日!G14,"") -> 12113.114 | F33: =IFERROR(30日!Q19,"") -> 22 | G33: =IFERROR(30日!P14,"") -> 19755 | H33: =IFERROR(30日!W14,"") -> 542975 | I33: =IFERROR(30日!AB19,"") -> 0 | J33: =IFERROR(30日!AF19,"") -> 31 | K33: =IFERROR(30日!AJ19,"") -> 2 | L33: =IFERROR(30日!AO4*24,"") -> 0.66666667 | M33: =IFERROR(30日!AR4*24,"") -> 0
A34: 31日 | B34: =IFERROR(31日!D4,"") -> 184.963 | C34: =IFERROR(31日!D9,"") -> 195.771 | D34: =IFERROR(31日!D14,"") -> 380.734 | E34: =IFERROR(31日!G14,"") -> 12493.848 | F34: =IFERROR(31日!Q19,"") -> 17 | G34: =IFERROR(31日!P14,"") -> 35408 | H34: =IFERROR(31日!W14,"") -> 578383 | I34: =IFERROR(31日!AB19,"") -> 0 | J34: =IFERROR(31日!AF19,"") -> 28 | K34: =IFERROR(31日!AJ19,"") -> 5 | L34: =IFERROR(31日!AO4*24,"") -> 1.6666667 | M34: =IFERROR(31日!AR4*24,"") -> 0
A35: 合計/平均 | B35: =SUM(B4:B34) -> 6061.265 | C35: =SUM(C4:C34) -> 6432.583 | D35: =SUM(D4:D34) -> 12493.848 | F35: =SUM(F4:F34) -> 656 | G35: =SUM(G4:G34) -> 578383 | I35: =SUM(I4:I34) -> 21 | J35: =SUM(J4:J34) -> 501 | K35: =SUM(K4:K34) -> 57 | L35: =SUM(L4:L34) -> 34.166667 | M35: =SUM(M4:M34) -> 6.5

Sheet 5CRカッター平包_月次
A1: （２）５C/Rカッター・平包 月次集計
A2: データ出典: 各日シート（1日～31日）へのリンク数式。数値は元シートの値がそのまま反映されます。
A3: 日 | B3: 1S/C処理量(t) | C3: 2S/C処理量(t) | D3: 3S/C処理量(t) | E3: 合計処理量(t) | F3: 合計累計(t) | G3: パルパー移送量(kg) | H3: #1平包(包) | I3: #1平包(t) | J3: #2平包(包) | K3: #2平包(t) | L3: #3平包(包) | M3: #3平包(t) | N3: 平包合計(包) | O3: 平包合計(t)
A4: 1日 | B4: =IFERROR(1日!F23,"") -> 31.3 | C4: =IFERROR(1日!F29,"") -> 62.5 | D4: =IFERROR(1日!F35,"") -> 26.6 | E4: =IFERROR(1日!F41,"") -> 120.4 | F4: =IFERROR(1日!I41,"") -> 120.4 | G4: =IFERROR(1日!T41,"") -> 23400 | H4: =IFERROR(VALUE(LEFT(1日!J43,FIND(" ",1日!J43)-1)),"") -> 2805 | I4: =IFERROR(VALUE(TRIM(SUBSTITUTE(MID(1日!J43,FIND("(",1日!J43)+1,FIND("t)",1日!J43)-FIND("(",1日!J43)-1),"t",""))),"") -> 62 | J4: =IFERROR(VALUE(LEFT(1日!J45,FIND(" ",1日!J45)-1)),"") -> 3307 | K4: =IFERROR(VALUE(TRIM(SUBSTITUTE(MID(1日!J45,FIND("(",1日!J45)+1,FIND("t)",1日!J45)-FIND("(",1日!J45)-1),"t",""))),"") -> 50 | L4: =IFERROR(VALUE(LEFT(1日!J47,FIND(" ",1日!J47)-1)),"") -> 0 | M4: =IFERROR(VALUE(TRIM(SUBSTITUTE(MID(1日!J47,FIND("(",1日!J47)+1,FIND("t)",1日!J47)-FIND("(",1日!J47)-1),"t",""))),"") -> 0 | N4: =IFERROR(VALUE(LEFT(1日!J49,FIND(" ",1日!J49)-1)),"") -> 6112 | O4: =IFERROR(VALUE(TRIM(SUBSTITUTE(MID(1日!J49,FIND("(",1日!J49)+1,FIND("t)",1日!J49)-FIND("(",1日!J49)-1),"t",""))),"") -> 112
A5: 2日 | B5: =IFERROR(2日!F23,"") -> 28.3 | C5: =IFERROR(2日!F29,"") -> 65.2 | D5: =IFERROR(2日!F35,"") -> 17.7 | E5: =IFERROR(2日!F41,"") -> 111.2 | F5: =IFERROR(2日!I41,"") -> 231.7 | G5: =IFERROR(2日!T41,"") -> 17400 | H5: =IFERROR(VALUE(LEFT(2日!J43,FIND(" ",2日!J43)-1)),"") -> 3059 | I5: =IFERROR(VALUE(TRIM(SUBSTITUTE(MID(2日!J43,FIND("(",2日!J43)+1,FIND("t)",2日!J43)-FIND("(",2日!J43)-1),"t",""))),"") -> 43 | J5: =IFERROR(VALUE(LEFT(2日!J45,FIND(" ",2日!J45)-1)),"") -> 2044 | K5: =IFERROR(VALUE(TRIM(SUBSTITUTE(MID(2日!J45,FIND("(",2日!J45)+1,FIND("t)",2日!J45)-FIND("(",2日!J45)-1),"t",""))),"") -> 37 | L5: =IFERROR(VALUE(LEFT(2日!J47,FIND(" ",2日!J47)-1)),"") -> 0 | M5: =IFERROR(VALUE(TRIM(SUBSTITUTE(MID(2日!J47,FIND("(",2日!J47)+1,FIND("t)",2日!J47)-FIND("(",2日!J47)-1),"t",""))),"") -> 0 | N5: =IFERROR(VALUE(LEFT(2日!J49,FIND(" ",2日!J49)-1)),"") -> 5103 | O5: =IFERROR(VALUE(TRIM(SUBSTITUTE(MID(2日!J49,FIND("(",2日!J49)+1,FIND("t)",2日!J49)-FIND("(",2日!J49)-1),"t",""))),"") -> 80
A6: 3日 | B6: =IFERROR(3日!F23,"") -> 58.2 | C6: =IFERROR(3日!F29,"") -> 85.3 | D6: =IFERROR(3日!F35,"") -> 57.4 | E6: =IFERROR(3日!F41,"") -> 200.9 | F6: =IFERROR(3日!I41,"") -> 432.7 | G6: =IFERROR(3日!T41,"") -> 3600 | H6: =IFERROR(VALUE(LEFT(3日!J43,FIND(" ",3日!J43)-1)),"") -> 2867 | I6: =IFERROR(VALUE(TRIM(SUBSTITUTE(MID(3日!J43,FIND("(",3日!J43)+1,FIND("t)",3日!J43)-FIND("(",3日!J43)-1),"t",""))),"") -> 60 | J6: =IFERROR(VALUE(LEFT(3日!J45,FIND(" ",3日!J45)-1)),"") -> 2831 | K6: =IFERROR(VALUE(TRIM(SUBSTITUTE(MID(3日!J45,FIND("(",3日!J45)+1,FIND("t)",3日!J45)-FIND("(",3日!J45)-1),"t",""))),"") -> 43 | L6: =IFERROR(VALUE(LEFT(3日!J47,FIND(" ",3日!J47)-1)),"") -> 0 | M6: =IFERROR(VALUE(TRIM(SUBSTITUTE(MID(3日!J47,FIND("(",3日!J47)+1,FIND("t)",3日!J47)-FIND("(",3日!J47)-1),"t",""))),"") -> 0 | N6: =IFERROR(VALUE(LEFT(3日!J49,FIND(" ",3日!J49)-1)),"") -> 5698 | O6: =IFERROR(VALUE(TRIM(SUBSTITUTE(MID(3日!J49,FIND("(",3日!J49)+1,FIND("t)",3日!J49)-FIND("(",3日!J49)-1),"t",""))),"") -> 103
A7: 4日 | B7: =IFERROR(4日!F23,"") -> 59 | C7: =IFERROR(4日!F29,"") -> 95.5 | D7: =IFERROR(4日!F35,"") -> 66.6 | E7: =IFERROR(4日!F41,"") -> 221.1 | F7: =IFERROR(4日!I41,"") -> 653.8 | G7: =IFERROR(4日!T41,"") -> 2400 | H7: =IFERROR(VALUE(LEFT(4日!J43,FIND(" ",4日!J43)-1)),"") -> 3194 | I7: =IFERROR(VALUE(TRIM(SUBSTITUTE(MID(4日!J43,FIND("(",4日!J43)+1,FIND("t)",4日!J43)-FIND("(",4日!J43)-1),"t",""))),"") -> 77 | J7: =IFERROR(VALUE(LEFT(4日!J45,FIND(" ",4日!J45)-1)),"") -> 4540 | K7: =IFERROR(VALUE(TRIM(SUBSTITUTE(MID(4日!J45,FIND("(",4日!J45)+1,FIND("t)",4日!J45)-FIND("(",4日!J45)-1),"t",""))),"") -> 79 | L7: =IFERROR(VALUE(LEFT(4日!J47,FIND(" ",4日!J47)-1)),"") -> 0 | M7: =IFERROR(VALUE(TRIM(SUBSTITUTE(MID(4日!J47,FIND("(",4日!J47)+1,FIND("t)",4日!J47)-FIND("(",4日!J47)-1),"t",""))),"") -> 0 | N7: =IFERROR(VALUE(LEFT(4日!J49,FIND(" ",4日!J49)-1)),"") -> 7734 | O7: =IFERROR(VALUE(TRIM(SUBSTITUTE(MID(4日!J49,FIND("(",4日!J49)+1,FIND("t)",4日!J49)-FIND("(",4日!J49)-1),"t",""))),"") -> 156
A8: 5日 | B8: =IFERROR(5日!F23,"") -> 27.8 | C8: =IFERROR(5日!F29,"") -> 65.6 | D8: =IFERROR(5日!F35,"") -> 58.6 | E8: =IFERROR(5日!F41,"") -> 152 | F8: =IFERROR(5日!I41,"") -> 805.8 | G8: =IFERROR(5日!T41,"") -> 36000 | H8: =IFERROR(VALUE(LEFT(5日!J43,FIND(" ",5日!J43)-1)),"") -> 2660 | I8: =IFERROR(VALUE(TRIM(SUBSTITUTE(MID(5日!J43,FIND("(",5日!J43)+1,FIND("t)",5日!J43)-FIND("(",5日!J43)-1),"t",""))),"") -> 52 | J8: =IFERROR(VALUE(LEFT(5日!J45,FIND(" ",5日!J45)-1)),"") -> 3093 | K8: =IFERROR(VALUE(TRIM(SUBSTITUTE(MID(5日!J45,FIND("(",5日!J45)+1,FIND("t)",5日!J45)-FIND("(",5日!J45)-1),"t",""))),"") -> 59 | L8: =IFERROR(VALUE(LEFT(5日!J47,FIND(" ",5日!J47)-1)),"") -> 0 | M8: =IFERROR(VALUE(TRIM(SUBSTITUTE(MID(5日!J47,FIND("(",5日!J47)+1,FIND("t)",5日!J47)-FIND("(",5日!J47)-1),"t",""))),"") -> 0 | N8: =IFERROR(VALUE(LEFT(5日!J49,FIND(" ",5日!J49)-1)),"") -> 5753 | O8: =IFERROR(VALUE(TRIM(SUBSTITUTE(MID(5日!J49,FIND("(",5日!J49)+1,FIND("t)",5日!J49)-FIND("(",5日!J49)-1),"t",""))),"") -> 111
A9: 6日 | B9: =IFERROR(6日!F23,"") -> 25.2 | C9: =IFERROR(6日!F29,"") -> 85.1 | D9: =IFERROR(6日!F35,"") -> 57.4 | E9: =IFERROR(6日!F41,"") -> 167.7 | F9: =IFERROR(6日!I41,"") -> 973.4 | G9: =IFERROR(6日!T41,"") -> 41400 | H9: =IFERROR(VALUE(LEFT(6日!J43,FIND(" ",6日!J43)-1)),"") -> 5148 | I9: =IFERROR(VALUE(TRIM(SUBSTITUTE(MID(6日!J43,FIND("(",6日!J43)+1,FIND("t)",6日!J43)-FIND("(",6日!J43)-1),"t",""))),"") -> 77 | J9: =IFERROR(VALUE(LEFT(6日!J45,FIND(" ",6日!J45)-1)),"") -> 2848 | K9: =IFERROR(VALUE(TRIM(SUBSTITUTE(MID(6日!J45,FIND("(",6日!J45)+1,FIND("t)",6日!J45)-FIND("(",6日!J45)-1),"t",""))),"") -> 47 | L9: =IFERROR(VALUE(LEFT(6日!J47,FIND(" ",6日!J47)-1)),"") -> 0 | M9: =IFERROR(VALUE(TRIM(SUBSTITUTE(MID(6日!J47,FIND("(",6日!J47)+1,FIND("t)",6日!J47)-FIND("(",6日!J47)-1),"t",""))),"") -> 0 | N9: =IFERROR(VALUE(LEFT(6日!J49,FIND(" ",6日!J49)-1)),"") -> 7996 | O9: =IFERROR(VALUE(TRIM(SUBSTITUTE(MID(6日!J49,FIND("(",6日!J49)+1,FIND("t)",6日!J49)-FIND("(",6日!J49)-1),"t",""))),"") -> 123
A10: 7日 | B10: =IFERROR(7日!F23,"") -> 38.1 | C10: =IFERROR(7日!F29,"") -> 63.6 | D10: =IFERROR(7日!F35,"") -> 39.5 | E10: =IFERROR(7日!F41,"") -> 141.2 | F10: =IFERROR(7日!I41,"") -> 1114.6 | G10: =IFERROR(7日!T41,"") -> 45600 | H10: =IFERROR(VALUE(LEFT(7日!J43,FIND(" ",7日!J43)-1)),"") -> 2816 | I10: =IFERROR(VALUE(TRIM(SUBSTITUTE(MID(7日!J43,FIND("(",7日!J43)+1,FIND("t)",7日!J43)-FIND("(",7日!J43)-1),"t",""))),"") -> 45 | J10: =IFERROR(VALUE(LEFT(7日!J45,FIND(" ",7日!J45)-1)),"") -> 5466 | K10: =IFERROR(VALUE(TRIM(SUBSTITUTE(MID(7日!J45,FIND("(",7日!J45)+1,FIND("t)",7日!J45)-FIND("(",7日!J45)-1),"t",""))),"") -> 85 | L10: =IFERROR(VALUE(LEFT(7日!J47,FIND(" ",7日!J47)-1)),"") -> 0 | M10: =IFERROR(VALUE(TRIM(SUBSTITUTE(MID(7日!J47,FIND("(",7日!J47)+1,FIND("t)",7日!J47)-FIND("(",7日!J47)-1),"t",""))),"") -> 0 | N10: =IFERROR(VALUE(LEFT(7日!J49,FIND(" ",7日!J49)-1)),"") -> 8282 | O10: =IFERROR(VALUE(TRIM(SUBSTITUTE(MID(7日!J49,FIND("(",7日!J49)+1,FIND("t)",7日!J49)-FIND("(",7日!J49)-1),"t",""))),"") -> 131
A11: 8日 | B11: =IFERROR(8日!F23,"") -> 55.3 | C11: =IFERROR(8日!F29,"") -> 53.9 | D11: =IFERROR(8日!F35,"") -> 38.8 | E11: =IFERROR(8日!F41,"") -> 148 | F11: =IFERROR(8日!I41,"") -> 1262.6 | G11: =IFERROR(8日!T41,"") -> 45600 | H11: =IFERROR(VALUE(LEFT(8日!J43,FIND(" ",8日!J43)-1)),"") -> 3732 | I11: =IFERROR(VALUE(TRIM(SUBSTITUTE(MID(8日!J43,FIND("(",8日!J43)+1,FIND("t)",8日!J43)-FIND("(",8日!J43)-1),"t",""))),"") -> 65 | J11: =IFERROR(VALUE(LEFT(8日!J45,FIND(" ",8日!J45)-1)),"") -> 4758 | K11: =IFERROR(VALUE(TRIM(SUBSTITUTE(MID(8日!J45,FIND("(",8日!J45)+1,FIND("t)",8日!J45)-FIND("(",8日!J45)-1),"t",""))),"") -> 85 | L11: =IFERROR(VALUE(LEFT(8日!J47,FIND(" ",8日!J47)-1)),"") -> 0 | M11: =IFERROR(VALUE(TRIM(SUBSTITUTE(MID(8日!J47,FIND("(",8日!J47)+1,FIND("t)",8日!J47)-FIND("(",8日!J47)-1),"t",""))),"") -> 0 | N11: =IFERROR(VALUE(LEFT(8日!J49,FIND(" ",8日!J49)-1)),"") -> 8490 | O11: =IFERROR(VALUE(TRIM(SUBSTITUTE(MID(8日!J49,FIND("(",8日!J49)+1,FIND("t)",8日!J49)-FIND("(",8日!J49)-1),"t",""))),"") -> 150
A12: 9日 | B12: =IFERROR(9日!F23,"") -> 24.7 | C12: =IFERROR(9日!F29,"") -> 81.6 | D12: =IFERROR(9日!F35,"") -> 36.4 | E12: =IFERROR(9日!F41,"") -> 142.7 | F12: =IFERROR(9日!I41,"") -> 1405.3 | G12: =IFERROR(9日!T41,"") -> 33600 | H12: =IFERROR(VALUE(LEFT(9日!J43,FIND(" ",9日!J43)-1)),"") -> 2924 | I12: =IFERROR(VALUE(TRIM(SUBSTITUTE(MID(9日!J43,FIND("(",9日!J43)+1,FIND("t)",9日!J43)-FIND("(",9日!J43)-1),"t",""))),"") -> 62 | J12: =IFERROR(VALUE(LEFT(9日!J45,FIND(" ",9日!J45)-1)),"") -> 2990 | K12: =IFERROR(VALUE(TRIM(SUBSTITUTE(MID(9日!J45,FIND("(",9日!J45)+1,FIND("t)",9日!J45)-FIND("(",9日!J45)-1),"t",""))),"") -> 54 | L12: =IFERROR(VALUE(LEFT(9日!J47,FIND(" ",9日!J47)-1)),"") -> 0 | M12: =IFERROR(VALUE(TRIM(SUBSTITUTE(MID(9日!J47,FIND("(",9日!J47)+1,FIND("t)",9日!J47)-FIND("(",9日!J47)-1),"t",""))),"") -> 0 | N12: =IFERROR(VALUE(LEFT(9日!J49,FIND(" ",9日!J49)-1)),"") -> 5914 | O12: =IFERROR(VALUE(TRIM(SUBSTITUTE(MID(9日!J49,FIND("(",9日!J49)+1,FIND("t)",9日!J49)-FIND("(",9日!J49)-1),"t",""))),"") -> 115
A13: 10日 | B13: =IFERROR(10日!F23,"") -> 35.5 | C13: =IFERROR(10日!F29,"") -> 52.8 | D13: =IFERROR(10日!F35,"") -> 43.3 | E13: =IFERROR(10日!F41,"") -> 131.6 | F13: =IFERROR(10日!I41,"") -> 1536.9 | G13: =IFERROR(10日!T41,"") -> 37200 | H13: =IFERROR(VALUE(LEFT(10日!J43,FIND(" ",10日!J43)-1)),"") -> 2049 | I13: =IFERROR(VALUE(TRIM(SUBSTITUTE(MID(10日!J43,FIND("(",10日!J43)+1,FIND("t)",10日!J43)-FIND("(",10日!J43)-1),"t",""))),"") -> 46 | J13: =IFERROR(VALUE(LEFT(10日!J45,FIND(" ",10日!J45)-1)),"") -> 3574 | K13: =IFERROR(VALUE(TRIM(SUBSTITUTE(MID(10日!J45,FIND("(",10日!J45)+1,FIND("t)",10日!J45)-FIND("(",10日!J45)-1),"t",""))),"") -> 61 | L13: =IFERROR(VALUE(LEFT(10日!J47,FIND(" ",10日!J47)-1)),"") -> 0 | M13: =IFERROR(VALUE(TRIM(SUBSTITUTE(MID(10日!J47,FIND("(",10日!J47)+1,FIND("t)",10日!J47)-FIND("(",10日!J47)-1),"t",""))),"") -> 0 | N13: =IFERROR(VALUE(LEFT(10日!J49,FIND(" ",10日!J49)-1)),"") -> 5623 | O13: =IFERROR(VALUE(TRIM(SUBSTITUTE(MID(10日!J49,FIND("(",10日!J49)+1,FIND("t)",10日!J49)-FIND("(",10日!J49)-1),"t",""))),"") -> 107
A14: 11日 | B14: =IFERROR(11日!F23,"") -> 74 | C14: =IFERROR(11日!F29,"") -> 91.7 | D14: =IFERROR(11日!F35,"") -> 36.6 | E14: =IFERROR(11日!F41,"") -> 202.3 | F14: =IFERROR(11日!I41,"") -> 1739 | G14: =IFERROR(11日!T41,"") -> 20400 | H14: =IFERROR(VALUE(LEFT(11日!J43,FIND(" ",11日!J43)-1)),"") -> 5787 | I14: =IFERROR(VALUE(TRIM(SUBSTITUTE(MID(11日!J43,FIND("(",11日!J43)+1,FIND("t)",11日!J43)-FIND("(",11日!J43)-1),"t",""))),"") -> 104 | J14: =IFERROR(VALUE(LEFT(11日!J45,FIND(" ",11日!J45)-1)),"") -> 3343 | K14: =IFERROR(VALUE(TRIM(SUBSTITUTE(MID(11日!J45,FIND("(",11日!J45)+1,FIND("t)",11日!J45)-FIND("(",11日!J45)-1),"t",""))),"") -> 58 | L14: =IFERROR(VALUE(LEFT(11日!J47,FIND(" ",11日!J47)-1)),"") -> 0 | M14: =IFERROR(VALUE(TRIM(SUBSTITUTE(MID(11日!J47,FIND("(",11日!J47)+1,FIND("t)",11日!J47)-FIND("(",11日!J47)-1),"t",""))),"") -> 0 | N14: =IFERROR(VALUE(LEFT(11日!J49,FIND(" ",11日!J49)-1)),"") -> 9130 | O14: =IFERROR(VALUE(TRIM(SUBSTITUTE(MID(11日!J49,FIND("(",11日!J49)+1,FIND("t)",11日!J49)-FIND("(",11日!J49)-1),"t",""))),"") -> 162
A15: 12日 | B15: =IFERROR(12日!F23,"") -> 48.2 | C15: =IFERROR(12日!F29,"") -> 90.3 | D15: =IFERROR(12日!F35,"") -> 48.9 | E15: =IFERROR(12日!F41,"") -> 187.4 | F15: =IFERROR(12日!I41,"") -> 1926.4 | G15: =IFERROR(12日!T41,"") -> 19200 | H15: =IFERROR(VALUE(LEFT(12日!J43,FIND(" ",12日!J43)-1)),"") -> 5018 | I15: =IFERROR(VALUE(TRIM(SUBSTITUTE(MID(12日!J43,FIND("(",12日!J43)+1,FIND("t)",12日!J43)-FIND("(",12日!J43)-1),"t",""))),"") -> 85 | J15: =IFERROR(VALUE(LEFT(12日!J45,FIND(" ",12日!J45)-1)),"") -> 2836 | K15: =IFERROR(VALUE(TRIM(SUBSTITUTE(MID(12日!J45,FIND("(",12日!J45)+1,FIND("t)",12日!J45)-FIND("(",12日!J45)-1),"t",""))),"") -> 63 | L15: =IFERROR(VALUE(LEFT(12日!J47,FIND(" ",12日!J47)-1)),"") -> 0 | M15: =IFERROR(VALUE(TRIM(SUBSTITUTE(MID(12日!J47,FIND("(",12日!J47)+1,FIND("t)",12日!J47)-FIND("(",12日!J47)-1),"t",""))),"") -> 0 | N15: =IFERROR(VALUE(LEFT(12日!J49,FIND(" ",12日!J49)-1)),"") -> 7854 | O15: =IFERROR(VALUE(TRIM(SUBSTITUTE(MID(12日!J49,FIND("(",12日!J49)+1,FIND("t)",12日!J49)-FIND("(",12日!J49)-1),"t",""))),"") -> 148
A16: 13日 | B16: =IFERROR(13日!F23,"") -> 55.9 | C16: =IFERROR(13日!F29,"") -> 87.2 | D16: =IFERROR(13日!F35,"") -> 12.8 | E16: =IFERROR(13日!F41,"") -> 155.9 | F16: =IFERROR(13日!I41,"") -> 2082.4 | G16: =IFERROR(13日!T41,"") -> 30600 | H16: =IFERROR(VALUE(LEFT(13日!J43,FIND(" ",13日!J43)-1)),"") -> 3093 | I16: =IFERROR(VALUE(TRIM(SUBSTITUTE(MID(13日!J43,FIND("(",13日!J43)+1,FIND("t)",13日!J43)-FIND("(",13日!J43)-1),"t",""))),"") -> 45 | J16: =IFERROR(VALUE(LEFT(13日!J45,FIND(" ",13日!J45)-1)),"") -> 2740 | K16: =IFERROR(VALUE(TRIM(SUBSTITUTE(MID(13日!J45,FIND("(",13日!J45)+1,FIND("t)",13日!J45)-FIND("(",13日!J45)-1),"t",""))),"") -> 51 | L16: =IFERROR(VALUE(LEFT(13日!J47,FIND(" ",13日!J47)-1)),"") -> 0 | M16: =IFERROR(VALUE(TRIM(SUBSTITUTE(MID(13日!J47,FIND("(",13日!J47)+1,FIND("t)",13日!J47)-FIND("(",13日!J47)-1),"t",""))),"") -> 0 | N16: =IFERROR(VALUE(LEFT(13日!J49,FIND(" ",13日!J49)-1)),"") -> 5833 | O16: =IFERROR(VALUE(TRIM(SUBSTITUTE(MID(13日!J49,FIND("(",13日!J49)+1,FIND("t)",13日!J49)-FIND("(",13日!J49)-1),"t",""))),"") -> 96
A17: 14日 | B17: =IFERROR(14日!F23,"") -> 84.3 | C17: =IFERROR(14日!F29,"") -> 66.6 | D17: =IFERROR(14日!F35,"") -> 26.6 | E17: =IFERROR(14日!F41,"") -> 177.5 | F17: =IFERROR(14日!I41,"") -> 2259.9 | G17: =IFERROR(14日!T41,"") -> 28200 | H17: =IFERROR(VALUE(LEFT(14日!J43,FIND(" ",14日!J43)-1)),"") -> 4889 | I17: =IFERROR(VALUE(TRIM(SUBSTITUTE(MID(14日!J43,FIND("(",14日!J43)+1,FIND("t)",14日!J43)-FIND("(",14日!J43)-1),"t",""))),"") -> 72 | J17: =IFERROR(VALUE(LEFT(14日!J45,FIND(" ",14日!J45)-1)),"") -> 3636 | K17: =IFERROR(VALUE(TRIM(SUBSTITUTE(MID(14日!J45,FIND("(",14日!J45)+1,FIND("t)",14日!J45)-FIND("(",14日!J45)-1),"t",""))),"") -> 63 | L17: =IFERROR(VALUE(LEFT(14日!J47,FIND(" ",14日!J47)-1)),"") -> 0 | M17: =IFERROR(VALUE(TRIM(SUBSTITUTE(MID(14日!J47,FIND("(",14日!J47)+1,FIND("t)",14日!J47)-FIND("(",14日!J47)-1),"t",""))),"") -> 0 | N17: =IFERROR(VALUE(LEFT(14日!J49,FIND(" ",14日!J49)-1)),"") -> 8525 | O17: =IFERROR(VALUE(TRIM(SUBSTITUTE(MID(14日!J49,FIND("(",14日!J49)+1,FIND("t)",14日!J49)-FIND("(",14日!J49)-1),"t",""))),"") -> 135
A18: 15日 | B18: =IFERROR(15日!F23,"") -> 64.8 | C18: =IFERROR(15日!F29,"") -> 69.5 | D18: =IFERROR(15日!F35,"") -> 17 | E18: =IFERROR(15日!F41,"") -> 151.3 | F18: =IFERROR(15日!I41,"") -> 2411 | G18: =IFERROR(15日!T41,"") -> 12000 | H18: =IFERROR(VALUE(LEFT(15日!J43,FIND(" ",15日!J43)-1)),"") -> 5184 | I18: =IFERROR(VALUE(TRIM(SUBSTITUTE(MID(15日!J43,FIND("(",15日!J43)+1,FIND("t)",15日!J43)-FIND("(",15日!J43)-1),"t",""))),"") -> 95 | J18: =IFERROR(VALUE(LEFT(15日!J45,FIND(" ",15日!J45)-1)),"") -> 2638 | K18: =IFERROR(VALUE(TRIM(SUBSTITUTE(MID(15日!J45,FIND("(",15日!J45)+1,FIND("t)",15日!J45)-FIND("(",15日!J45)-1),"t",""))),"") -> 64 | L18: =IFERROR(VALUE(LEFT(15日!J47,FIND(" ",15日!J47)-1)),"") -> 0 | M18: =IFERROR(VALUE(TRIM(SUBSTITUTE(MID(15日!J47,FIND("(",15日!J47)+1,FIND("t)",15日!J47)-FIND("(",15日!J47)-1),"t",""))),"") -> 0 | N18: =IFERROR(VALUE(LEFT(15日!J49,FIND(" ",15日!J49)-1)),"") -> 7822 | O18: =IFERROR(VALUE(TRIM(SUBSTITUTE(MID(15日!J49,FIND("(",15日!J49)+1,FIND("t)",15日!J49)-FIND("(",15日!J49)-1),"t",""))),"") -> 159
A19: 16日 | B19: =IFERROR(16日!F23,"") -> 54.7 | C19: =IFERROR(16日!F29,"") -> 72.7 | D19: =IFERROR(16日!F35,"") -> 44.7 | E19: =IFERROR(16日!F41,"") -> 172.1 | F19: =IFERROR(16日!I41,"") -> 2583.1 | G19: =IFERROR(16日!T41,"") -> 1200 | H19: =IFERROR(VALUE(LEFT(16日!J43,FIND(" ",16日!J43)-1)),"") -> 5418 | I19: =IFERROR(VALUE(TRIM(SUBSTITUTE(MID(16日!J43,FIND("(",16日!J43)+1,FIND("t)",16日!J43)-FIND("(",16日!J43)-1),"t",""))),"") -> 88 | J19: =IFERROR(VALUE(LEFT(16日!J45,FIND(" ",16日!J45)-1)),"") -> 2430 | K19: =IFERROR(VALUE(TRIM(SUBSTITUTE(MID(16日!J45,FIND("(",16日!J45)+1,FIND("t)",16日!J45)-FIND("(",16日!J45)-1),"t",""))),"") -> 57 | L19: =IFERROR(VALUE(LEFT(16日!J47,FIND(" ",16日!J47)-1)),"") -> 0 | M19: =IFERROR(VALUE(TRIM(SUBSTITUTE(MID(16日!J47,FIND("(",16日!J47)+1,FIND("t)",16日!J47)-FIND("(",16日!J47)-1),"t",""))),"") -> 0 | N19: =IFERROR(VALUE(LEFT(16日!J49,FIND(" ",16日!J49)-1)),"") -> 7848 | O19: =IFERROR(VALUE(TRIM(SUBSTITUTE(MID(16日!J49,FIND("(",16日!J49)+1,FIND("t)",16日!J49)-FIND("(",16日!J49)-1),"t",""))),"") -> 146
A20: 17日 | B20: =IFERROR(17日!F23,"") -> 65.7 | C20: =IFERROR(17日!F29,"") -> 22.3 | D20: =IFERROR(17日!F35,"") -> 29.1 | E20: =IFERROR(17日!F41,"") -> 117.1 | F20: =IFERROR(17日!I41,"") -> 2700.3 | G20: =IFERROR(17日!T41,"") -> 3600 | H20: =IFERROR(VALUE(LEFT(17日!J43,FIND(" ",17日!J43)-1)),"") -> 4710 | I20: =IFERROR(VALUE(TRIM(SUBSTITUTE(MID(17日!J43,FIND("(",17日!J43)+1,FIND("t)",17日!J43)-FIND("(",17日!J43)-1),"t",""))),"") -> 70 | J20: =IFERROR(VALUE(LEFT(17日!J45,FIND(" ",17日!J45)-1)),"") -> 1399 | K20: =IFERROR(VALUE(TRIM(SUBSTITUTE(MID(17日!J45,FIND("(",17日!J45)+1,FIND("t)",17日!J45)-FIND("(",17日!J45)-1),"t",""))),"") -> 27 | L20: =IFERROR(VALUE(LEFT(17日!J47,FIND(" ",17日!J47)-1)),"") -> 0 | M20: =IFERROR(VALUE(TRIM(SUBSTITUTE(MID(17日!J47,FIND("(",17日!J47)+1,FIND("t)",17日!J47)-FIND("(",17日!J47)-1),"t",""))),"") -> 0 | N20: =IFERROR(VALUE(LEFT(17日!J49,FIND(" ",17日!J49)-1)),"") -> 6109 | O20: =IFERROR(VALUE(TRIM(SUBSTITUTE(MID(17日!J49,FIND("(",17日!J49)+1,FIND("t)",17日!J49)-FIND("(",17日!J49)-1),"t",""))),"") -> 97
A21: 18日 | B21: =IFERROR(18日!F23,"") -> 16.3 | C21: =IFERROR(18日!F29,"") -> 42.9 | D21: =IFERROR(18日!F35,"") -> 45.1 | E21: =IFERROR(18日!F41,"") -> 104.3 | F21: =IFERROR(18日!I41,"") -> 2804.6 | G21: =IFERROR(18日!T41,"") -> 7200 | H21: =IFERROR(VALUE(LEFT(18日!J43,FIND(" ",18日!J43)-1)),"") -> 2408 | I21: =IFERROR(VALUE(TRIM(SUBSTITUTE(MID(18日!J43,FIND("(",18日!J43)+1,FIND("t)",18日!J43)-FIND("(",18日!J43)-1),"t",""))),"") -> 33 | J21: =IFERROR(VALUE(LEFT(18日!J45,FIND(" ",18日!J45)-1)),"") -> 3384 | K21: =IFERROR(VALUE(TRIM(SUBSTITUTE(MID(18日!J45,FIND("(",18日!J45)+1,FIND("t)",18日!J45)-FIND("(",18日!J45)-1),"t",""))),"") -> 60 | L21: =IFERROR(VALUE(LEFT(18日!J47,FIND(" ",18日!J47)-1)),"") -> 0 | M21: =IFERROR(VALUE(TRIM(SUBSTITUTE(MID(18日!J47,FIND("(",18日!J47)+1,FIND("t)",18日!J47)-FIND("(",18日!J47)-1),"t",""))),"") -> 0 | N21: =IFERROR(VALUE(LEFT(18日!J49,FIND(" ",18日!J49)-1)),"") -> 5792 | O21: =IFERROR(VALUE(TRIM(SUBSTITUTE(MID(18日!J49,FIND("(",18日!J49)+1,FIND("t)",18日!J49)-FIND("(",18日!J49)-1),"t",""))),"") -> 93
A22: 19日 | B22: =IFERROR(19日!F23,"") -> 38.9 | C22: =IFERROR(19日!F29,"") -> 8.2 | D22: =IFERROR(19日!F35,"") -> 5.2 | E22: =IFERROR(19日!F41,"") -> 52.3 | F22: =IFERROR(19日!I41,"") -> 2856.9 | G22: =IFERROR(19日!T41,"") -> 30000 | H22: =IFERROR(VALUE(LEFT(19日!J43,FIND(" ",19日!J43)-1)),"") -> 3124 | I22: =IFERROR(VALUE(TRIM(SUBSTITUTE(MID(19日!J43,FIND("(",19日!J43)+1,FIND("t)",19日!J43)-FIND("(",19日!J43)-1),"t",""))),"") -> 47 | J22: =IFERROR(VALUE(LEFT(19日!J45,FIND(" ",19日!J45)-1)),"") -> 2381 | K22: =IFERROR(VALUE(TRIM(SUBSTITUTE(MID(19日!J45,FIND("(",19日!J45)+1,FIND("t)",19日!J45)-FIND("(",19日!J45)-1),"t",""))),"") -> 34 | L22: =IFERROR(VALUE(LEFT(19日!J47,FIND(" ",19日!J47)-1)),"") -> 0 | M22: =IFERROR(VALUE(TRIM(SUBSTITUTE(MID(19日!J47,FIND("(",19日!J47)+1,FIND("t)",19日!J47)-FIND("(",19日!J47)-1),"t",""))),"") -> 0 | N22: =IFERROR(VALUE(LEFT(19日!J49,FIND(" ",19日!J49)-1)),"") -> 5505 | O22: =IFERROR(VALUE(TRIM(SUBSTITUTE(MID(19日!J49,FIND("(",19日!J49)+1,FIND("t)",19日!J49)-FIND("(",19日!J49)-1),"t",""))),"") -> 81
A23: 20日 | B23: =IFERROR(20日!F23,"") -> 45.2 | C23: =IFERROR(20日!F29,"") -> 58.9 | D23: =IFERROR(20日!F35,"") -> 37.2 | E23: =IFERROR(20日!F41,"") -> 141.3 | F23: =IFERROR(20日!I41,"") -> 2998.2 | G23: =IFERROR(20日!T41,"") -> 20400 | H23: =IFERROR(VALUE(LEFT(20日!J43,FIND(" ",20日!J43)-1)),"") -> 2662 | I23: =IFERROR(VALUE(TRIM(SUBSTITUTE(MID(20日!J43,FIND("(",20日!J43)+1,FIND("t)",20日!J43)-FIND("(",20日!J43)-1),"t",""))),"") -> 40 | J23: =IFERROR(VALUE(LEFT(20日!J45,FIND(" ",20日!J45)-1)),"") -> 3404 | K23: =IFERROR(VALUE(TRIM(SUBSTITUTE(MID(20日!J45,FIND("(",20日!J45)+1,FIND("t)",20日!J45)-FIND("(",20日!J45)-1),"t",""))),"") -> 59 | L23: =IFERROR(VALUE(LEFT(20日!J47,FIND(" ",20日!J47)-1)),"") -> 0 | M23: =IFERROR(VALUE(TRIM(SUBSTITUTE(MID(20日!J47,FIND("(",20日!J47)+1,FIND("t)",20日!J47)-FIND("(",20日!J47)-1),"t",""))),"") -> 0 | N23: =IFERROR(VALUE(LEFT(20日!J49,FIND(" ",20日!J49)-1)),"") -> 6066 | O23: =IFERROR(VALUE(TRIM(SUBSTITUTE(MID(20日!J49,FIND("(",20日!J49)+1,FIND("t)",20日!J49)-FIND("(",20日!J49)-1),"t",""))),"") -> 99
A24: 21日 | B24: =IFERROR(21日!F23,"") -> 37.7 | C24: =IFERROR(21日!F29,"") -> 87.3 | D24: =IFERROR(21日!F35,"") -> 50.8 | E24: =IFERROR(21日!F41,"") -> 175.8 | F24: =IFERROR(21日!I41,"") -> 3174 | G24: =IFERROR(21日!T41,"") -> 49800 | H24: =IFERROR(VALUE(LEFT(21日!J43,FIND(" ",21日!J43)-1)),"") -> 1558 | I24: =IFERROR(VALUE(TRIM(SUBSTITUTE(MID(21日!J43,FIND("(",21日!J43)+1,FIND("t)",21日!J43)-FIND("(",21日!J43)-1),"t",""))),"") -> 36 | J24: =IFERROR(VALUE(LEFT(21日!J45,FIND(" ",21日!J45)-1)),"") -> 5683 | K24: =IFERROR(VALUE(TRIM(SUBSTITUTE(MID(21日!J45,FIND("(",21日!J45)+1,FIND("t)",21日!J45)-FIND("(",21日!J45)-1),"t",""))),"") -> 98 | L24: =IFERROR(VALUE(LEFT(21日!J47,FIND(" ",21日!J47)-1)),"") -> 0 | M24: =IFERROR(VALUE(TRIM(SUBSTITUTE(MID(21日!J47,FIND("(",21日!J47)+1,FIND("t)",21日!J47)-FIND("(",21日!J47)-1),"t",""))),"") -> 0 | N24: =IFERROR(VALUE(LEFT(21日!J49,FIND(" ",21日!J49)-1)),"") -> 7241 | O24: =IFERROR(VALUE(TRIM(SUBSTITUTE(MID(21日!J49,FIND("(",21日!J49)+1,FIND("t)",21日!J49)-FIND("(",21日!J49)-1),"t",""))),"") -> 134
A25: 22日 | B25: =IFERROR(22日!F23,"") -> 70.3 | C25: =IFERROR(22日!F29,"") -> 70.5 | D25: =IFERROR(22日!F35,"") -> 37.1 | E25: =IFERROR(22日!F41,"") -> 177.9 | F25: =IFERROR(22日!I41,"") -> 3351.8 | G25: =IFERROR(22日!T41,"") -> 9000 | H25: =IFERROR(VALUE(LEFT(22日!J43,FIND(" ",22日!J43)-1)),"") -> 2272 | I25: =IFERROR(VALUE(TRIM(SUBSTITUTE(MID(22日!J43,FIND("(",22日!J43)+1,FIND("t)",22日!J43)-FIND("(",22日!J43)-1),"t",""))),"") -> 56 | J25: =IFERROR(VALUE(LEFT(22日!J45,FIND(" ",22日!J45)-1)),"") -> 5564 | K25: =IFERROR(VALUE(TRIM(SUBSTITUTE(MID(22日!J45,FIND("(",22日!J45)+1,FIND("t)",22日!J45)-FIND("(",22日!J45)-1),"t",""))),"") -> 90 | L25: =IFERROR(VALUE(LEFT(22日!J47,FIND(" ",22日!J47)-1)),"") -> 0 | M25: =IFERROR(VALUE(TRIM(SUBSTITUTE(MID(22日!J47,FIND("(",22日!J47)+1,FIND("t)",22日!J47)-FIND("(",22日!J47)-1),"t",""))),"") -> 0 | N25: =IFERROR(VALUE(LEFT(22日!J49,FIND(" ",22日!J49)-1)),"") -> 7836 | O25: =IFERROR(VALUE(TRIM(SUBSTITUTE(MID(22日!J49,FIND("(",22日!J49)+1,FIND("t)",22日!J49)-FIND("(",22日!J49)-1),"t",""))),"") -> 146
A26: 23日 | B26: =IFERROR(23日!F23,"") -> 51.1 | C26: =IFERROR(23日!F29,"") -> 75.7 | D26: =IFERROR(23日!F35,"") -> 52.1 | E26: =IFERROR(23日!F41,"") -> 178.9 | F26: =IFERROR(23日!I41,"") -> 3530.8 | G26: =IFERROR(23日!T41,"") -> 25200 | H26: =IFERROR(VALUE(LEFT(23日!J43,FIND(" ",23日!J43)-1)),"") -> 3366 | I26: =IFERROR(VALUE(TRIM(SUBSTITUTE(MID(23日!J43,FIND("(",23日!J43)+1,FIND("t)",23日!J43)-FIND("(",23日!J43)-1),"t",""))),"") -> 55 | J26: =IFERROR(VALUE(LEFT(23日!J45,FIND(" ",23日!J45)-1)),"") -> 6050 | K26: =IFERROR(VALUE(TRIM(SUBSTITUTE(MID(23日!J45,FIND("(",23日!J45)+1,FIND("t)",23日!J45)-FIND("(",23日!J45)-1),"t",""))),"") -> 94 | L26: =IFERROR(VALUE(LEFT(23日!J47,FIND(" ",23日!J47)-1)),"") -> 0 | M26: =IFERROR(VALUE(TRIM(SUBSTITUTE(MID(23日!J47,FIND("(",23日!J47)+1,FIND("t)",23日!J47)-FIND("(",23日!J47)-1),"t",""))),"") -> 0 | N26: =IFERROR(VALUE(LEFT(23日!J49,FIND(" ",23日!J49)-1)),"") -> 9416 | O26: =IFERROR(VALUE(TRIM(SUBSTITUTE(MID(23日!J49,FIND("(",23日!J49)+1,FIND("t)",23日!J49)-FIND("(",23日!J49)-1),"t",""))),"") -> 149
A27: 24日 | B27: =IFERROR(24日!F23,"") -> 50.3 | C27: =IFERROR(24日!F29,"") -> 94 | D27: =IFERROR(24日!F35,"") -> 43.2 | E27: =IFERROR(24日!F41,"") -> 187.5 | F27: =IFERROR(24日!I41,"") -> 3718.2 | G27: =IFERROR(24日!T41,"") -> 48000 | H27: =IFERROR(VALUE(LEFT(24日!J43,FIND(" ",24日!J43)-1)),"") -> 3542 | I27: =IFERROR(VALUE(TRIM(SUBSTITUTE(MID(24日!J43,FIND("(",24日!J43)+1,FIND("t)",24日!J43)-FIND("(",24日!J43)-1),"t",""))),"") -> 56 | J27: =IFERROR(VALUE(LEFT(24日!J45,FIND(" ",24日!J45)-1)),"") -> 8096 | K27: =IFERROR(VALUE(TRIM(SUBSTITUTE(MID(24日!J45,FIND("(",24日!J45)+1,FIND("t)",24日!J45)-FIND("(",24日!J45)-1),"t",""))),"") -> 116 | L27: =IFERROR(VALUE(LEFT(24日!J47,FIND(" ",24日!J47)-1)),"") -> 0 | M27: =IFERROR(VALUE(TRIM(SUBSTITUTE(MID(24日!J47,FIND("(",24日!J47)+1,FIND("t)",24日!J47)-FIND("(",24日!J47)-1),"t",""))),"") -> 0 | N27: =IFERROR(VALUE(LEFT(24日!J49,FIND(" ",24日!J49)-1)),"") -> 11638 | O27: =IFERROR(VALUE(TRIM(SUBSTITUTE(MID(24日!J49,FIND("(",24日!J49)+1,FIND("t)",24日!J49)-FIND("(",24日!J49)-1),"t",""))),"") -> 172
A28: 25日 | B28: =IFERROR(25日!F23,"") -> 46.7 | C28: =IFERROR(25日!F29,"") -> 86.2 | D28: =IFERROR(25日!F35,"") -> 10 | E28: =IFERROR(25日!F41,"") -> 142.9 | F28: =IFERROR(25日!I41,"") -> 3861 | G28: =IFERROR(25日!T41,"") -> 18600 | H28: =IFERROR(VALUE(LEFT(25日!J43,FIND(" ",25日!J43)-1)),"") -> 2307 | I28: =IFERROR(VALUE(TRIM(SUBSTITUTE(MID(25日!J43,FIND("(",25日!J43)+1,FIND("t)",25日!J43)-FIND("(",25日!J43)-1),"t",""))),"") -> 56 | J28: =IFERROR(VALUE(LEFT(25日!J45,FIND(" ",25日!J45)-1)),"") -> 4137 | K28: =IFERROR(VALUE(TRIM(SUBSTITUTE(MID(25日!J45,FIND("(",25日!J45)+1,FIND("t)",25日!J45)-FIND("(",25日!J45)-1),"t",""))),"") -> 60 | L28: =IFERROR(VALUE(LEFT(25日!J47,FIND(" ",25日!J47)-1)),"") -> 0 | M28: =IFERROR(VALUE(TRIM(SUBSTITUTE(MID(25日!J47,FIND("(",25日!J47)+1,FIND("t)",25日!J47)-FIND("(",25日!J47)-1),"t",""))),"") -> 0 | N28: =IFERROR(VALUE(LEFT(25日!J49,FIND(" ",25日!J49)-1)),"") -> 6444 | O28: =IFERROR(VALUE(TRIM(SUBSTITUTE(MID(25日!J49,FIND("(",25日!J49)+1,FIND("t)",25日!J49)-FIND("(",25日!J49)-1),"t",""))),"") -> 116
A29: 26日 | B29: =IFERROR(26日!F23,"") -> 11.4 | C29: =IFERROR(26日!F29,"") -> 41.5 | D29: =IFERROR(26日!F35,"") -> 0 | E29: =IFERROR(26日!F41,"") -> 52.9 | F29: =IFERROR(26日!I41,"") -> 3914 | G29: =IFERROR(26日!T41,"") -> 33000 | H29: =IFERROR(VALUE(LEFT(26日!J43,FIND(" ",26日!J43)-1)),"") -> 2410 | I29: =IFERROR(VALUE(TRIM(SUBSTITUTE(MID(26日!J43,FIND("(",26日!J43)+1,FIND("t)",26日!J43)-FIND("(",26日!J43)-1),"t",""))),"") -> 41 | J29: =IFERROR(VALUE(LEFT(26日!J45,FIND(" ",26日!J45)-1)),"") -> 3685 | K29: =IFERROR(VALUE(TRIM(SUBSTITUTE(MID(26日!J45,FIND("(",26日!J45)+1,FIND("t)",26日!J45)-FIND("(",26日!J45)-1),"t",""))),"") -> 57 | L29: =IFERROR(VALUE(LEFT(26日!J47,FIND(" ",26日!J47)-1)),"") -> 0 | M29: =IFERROR(VALUE(TRIM(SUBSTITUTE(MID(26日!J47,FIND("(",26日!J47)+1,FIND("t)",26日!J47)-FIND("(",26日!J47)-1),"t",""))),"") -> 0 | N29: =IFERROR(VALUE(LEFT(26日!J49,FIND(" ",26日!J49)-1)),"") -> 6095 | O29: =IFERROR(VALUE(TRIM(SUBSTITUTE(MID(26日!J49,FIND("(",26日!J49)+1,FIND("t)",26日!J49)-FIND("(",26日!J49)-1),"t",""))),"") -> 98
A30: 27日 | B30: =IFERROR(27日!F23,"") -> 16.5 | C30: =IFERROR(27日!F29,"") -> 0 | D30: =IFERROR(27日!F35,"") -> 10.3 | E30: =IFERROR(27日!F41,"") -> 26.8 | F30: =IFERROR(27日!I41,"") -> 3941 | G30: =IFERROR(27日!T41,"") -> 42000 | H30: =IFERROR(VALUE(LEFT(27日!J43,FIND(" ",27日!J43)-1)),"") -> 43 | I30: =IFERROR(VALUE(TRIM(SUBSTITUTE(MID(27日!J43,FIND("(",27日!J43)+1,FIND("t)",27日!J43)-FIND("(",27日!J43)-1),"t",""))),"") -> 1 | J30: =IFERROR(VALUE(LEFT(27日!J45,FIND(" ",27日!J45)-1)),"") -> 1256 | K30: =IFERROR(VALUE(TRIM(SUBSTITUTE(MID(27日!J45,FIND("(",27日!J45)+1,FIND("t)",27日!J45)-FIND("(",27日!J45)-1),"t",""))),"") -> 18 | L30: =IFERROR(VALUE(LEFT(27日!J47,FIND(" ",27日!J47)-1)),"") -> 0 | M30: =IFERROR(VALUE(TRIM(SUBSTITUTE(MID(27日!J47,FIND("(",27日!J47)+1,FIND("t)",27日!J47)-FIND("(",27日!J47)-1),"t",""))),"") -> 0 | N30: =IFERROR(VALUE(LEFT(27日!J49,FIND(" ",27日!J49)-1)),"") -> 1299 | O30: =IFERROR(VALUE(TRIM(SUBSTITUTE(MID(27日!J49,FIND("(",27日!J49)+1,FIND("t)",27日!J49)-FIND("(",27日!J49)-1),"t",""))),"") -> 19
A31: 28日 | B31: =IFERROR(28日!F23,"") -> 48.2 | C31: =IFERROR(28日!F29,"") -> 63.9 | D31: =IFERROR(28日!F35,"") -> 44.2 | E31: =IFERROR(28日!F41,"") -> 156.3 | F31: =IFERROR(28日!I41,"") -> 4097.1 | G31: =IFERROR(28日!T41,"") -> 31800 | H31: =IFERROR(VALUE(LEFT(28日!J43,FIND(" ",28日!J43)-1)),"") -> 2498 | I31: =IFERROR(VALUE(TRIM(SUBSTITUTE(MID(28日!J43,FIND("(",28日!J43)+1,FIND("t)",28日!J43)-FIND("(",28日!J43)-1),"t",""))),"") -> 45 | J31: =IFERROR(VALUE(LEFT(28日!J45,FIND(" ",28日!J45)-1)),"") -> 4011 | K31: =IFERROR(VALUE(TRIM(SUBSTITUTE(MID(28日!J45,FIND("(",28日!J45)+1,FIND("t)",28日!J45)-FIND("(",28日!J45)-1),"t",""))),"") -> 61 | L31: =IFERROR(VALUE(LEFT(28日!J47,FIND(" ",28日!J47)-1)),"") -> 0 | M31: =IFERROR(VALUE(TRIM(SUBSTITUTE(MID(28日!J47,FIND("(",28日!J47)+1,FIND("t)",28日!J47)-FIND("(",28日!J47)-1),"t",""))),"") -> 0 | N31: =IFERROR(VALUE(LEFT(28日!J49,FIND(" ",28日!J49)-1)),"") -> 6509 | O31: =IFERROR(VALUE(TRIM(SUBSTITUTE(MID(28日!J49,FIND("(",28日!J49)+1,FIND("t)",28日!J49)-FIND("(",28日!J49)-1),"t",""))),"") -> 106
A32: 29日 | B32: =IFERROR(29日!F23,"") -> 19.6 | C32: =IFERROR(29日!F29,"") -> 63.6 | D32: =IFERROR(29日!F35,"") -> 38.7 | E32: =IFERROR(29日!F41,"") -> 121.9 | F32: =IFERROR(29日!I41,"") -> 4219.1 | G32: =IFERROR(29日!T41,"") -> 36600 | H32: =IFERROR(VALUE(LEFT(29日!J43,FIND(" ",29日!J43)-1)),"") -> 2880 | I32: =IFERROR(VALUE(TRIM(SUBSTITUTE(MID(29日!J43,FIND("(",29日!J43)+1,FIND("t)",29日!J43)-FIND("(",29日!J43)-1),"t",""))),"") -> 59 | J32: =IFERROR(VALUE(LEFT(29日!J45,FIND(" ",29日!J45)-1)),"") -> 3500 | K32: =IFERROR(VALUE(TRIM(SUBSTITUTE(MID(29日!J45,FIND("(",29日!J45)+1,FIND("t)",29日!J45)-FIND("(",29日!J45)-1),"t",""))),"") -> 56 | L32: =IFERROR(VALUE(LEFT(29日!J47,FIND(" ",29日!J47)-1)),"") -> 0 | M32: =IFERROR(VALUE(TRIM(SUBSTITUTE(MID(29日!J47,FIND("(",29日!J47)+1,FIND("t)",29日!J47)-FIND("(",29日!J47)-1),"t",""))),"") -> 0 | N32: =IFERROR(VALUE(LEFT(29日!J49,FIND(" ",29日!J49)-1)),"") -> 6380 | O32: =IFERROR(VALUE(TRIM(SUBSTITUTE(MID(29日!J49,FIND("(",29日!J49)+1,FIND("t)",29日!J49)-FIND("(",29日!J49)-1),"t",""))),"") -> 115
A33: 30日 | B33: =IFERROR(30日!F23,"") -> 38.2 | C33: =IFERROR(30日!F29,"") -> 55.6 | D33: =IFERROR(30日!F35,"") -> 39.1 | E33: =IFERROR(30日!F41,"") -> 132.9 | F33: =IFERROR(30日!I41,"") -> 4352 | G33: =IFERROR(30日!T41,"") -> 31200 | H33: =IFERROR(VALUE(LEFT(30日!J43,FIND(" ",30日!J43)-1)),"") -> 1982 | I33: =IFERROR(VALUE(TRIM(SUBSTITUTE(MID(30日!J43,FIND("(",30日!J43)+1,FIND("t)",30日!J43)-FIND("(",30日!J43)-1),"t",""))),"") -> 43 | J33: =IFERROR(VALUE(LEFT(30日!J45,FIND(" ",30日!J45)-1)),"") -> 3761 | K33: =IFERROR(VALUE(TRIM(SUBSTITUTE(MID(30日!J45,FIND("(",30日!J45)+1,FIND("t)",30日!J45)-FIND("(",30日!J45)-1),"t",""))),"") -> 67 | L33: =IFERROR(VALUE(LEFT(30日!J47,FIND(" ",30日!J47)-1)),"") -> 0 | M33: =IFERROR(VALUE(TRIM(SUBSTITUTE(MID(30日!J47,FIND("(",30日!J47)+1,FIND("t)",30日!J47)-FIND("(",30日!J47)-1),"t",""))),"") -> 0 | N33: =IFERROR(VALUE(LEFT(30日!J49,FIND(" ",30日!J49)-1)),"") -> 5743 | O33: =IFERROR(VALUE(TRIM(SUBSTITUTE(MID(30日!J49,FIND("(",30日!J49)+1,FIND("t)",30日!J49)-FIND("(",30日!J49)-1),"t",""))),"") -> 110
A34: 31日 | B34: =IFERROR(31日!F23,"") -> 42.1 | C34: =IFERROR(31日!F29,"") -> 86.8 | D34: =IFERROR(31日!F35,"") -> 63.3 | E34: =IFERROR(31日!F41,"") -> 192.2 | F34: =IFERROR(31日!I41,"") -> 4544 | G34: =IFERROR(31日!T41,"") -> 12000 | H34: =IFERROR(VALUE(LEFT(31日!J43,FIND(" ",31日!J43)-1)),"") -> 3365 | I34: =IFERROR(VALUE(TRIM(SUBSTITUTE(MID(31日!J43,FIND("(",31日!J43)+1,FIND("t)",31日!J43)-FIND("(",31日!J43)-1),"t",""))),"") -> 71 | J34: =IFERROR(VALUE(LEFT(31日!J45,FIND(" ",31日!J45)-1)),"") -> 4344 | K34: =IFERROR(VALUE(TRIM(SUBSTITUTE(MID(31日!J45,FIND("(",31日!J45)+1,FIND("t)",31日!J45)-FIND("(",31日!J45)-1),"t",""))),"") -> 67 | L34: =IFERROR(VALUE(LEFT(31日!J47,FIND(" ",31日!J47)-1)),"") -> 0 | M34: =IFERROR(VALUE(TRIM(SUBSTITUTE(MID(31日!J47,FIND("(",31日!J47)+1,FIND("t)",31日!J47)-FIND("(",31日!J47)-1),"t",""))),"") -> 0 | N34: =IFERROR(VALUE(LEFT(31日!J49,FIND(" ",31日!J49)-1)),"") -> 7709 | O34: =IFERROR(VALUE(TRIM(SUBSTITUTE(MID(31日!J49,FIND("(",31日!J49)+1,FIND("t)",31日!J49)-FIND("(",31日!J49)-1),"t",""))),"") -> 138
A35: 合計/平均 | B35: =SUM(B4:B34) -> 1363.5 | C35: =SUM(C4:C34) -> 2046.5 | D35: =SUM(D4:D34) -> 1134.3 | E35: =SUM(E4:E34) -> 4544.3 | G35: =SUM(G4:G34) -> 796200 | H35: =SUM(H4:H34) -> 99770 | I35: =SUM(I4:I34) -> 1787 | J35: =SUM(J4:J34) -> 113729 | K35: =SUM(K4:K34) -> 1920 | L35: =SUM(L4:L34) -> 0 | M35: =SUM(M4:M34) -> 0 | N35: =SUM(N4:N34) -> 213499 | O35: =SUM(O4:O34) -> 3707

Sheet 仕上2G_月次
A1: （３）仕上２Ｇ 月次集計
A2: データ出典: 各日シート（1日～31日）へのリンク数式。数値は元シートの値がそのまま反映されます。
A3: 日 | B3: 下台数 | C3: 総台数 | D3: 下の比率(%) | E3: 積替処理数 | F3: 積替累計 | G3: 未選別台数 | H3: 未仕上台数 | I3: 損紙発生量 実績 | J3: 損紙発生量 累計
A4: 1日 | B4: =IFERROR(1日!B58,"") -> 33 | C4: =IFERROR(1日!F58,"") -> 216 | D4: =IFERROR(1日!J58,"") -> 15.277778 | E4: =IFERROR(1日!G65,"") -> 0 | F4: =IFERROR(1日!K65,"") -> 0 | G4: =IFERROR(1日!P65,"") -> 90 | H4: =IFERROR(1日!T65,"") -> 114 | I4: =IFERROR(1日!Y65,"") -> 4 | J4: =IFERROR(1日!Y68,"") -> 4
A5: 2日 | B5: =IFERROR(2日!B58,"") -> 35 | C5: =IFERROR(2日!F58,"") -> 196 | D5: =IFERROR(2日!J58,"") -> 17.857143 | E5: =IFERROR(2日!G65,"") -> 7 | F5: =IFERROR(2日!K65,"") -> 7 | G5: =IFERROR(2日!P65,"") -> 118 | H5: =IFERROR(2日!T65,"") -> 132 | I5: =IFERROR(2日!Y65,"") -> 6 | J5: =IFERROR(2日!Y68,"") -> 10
A6: 3日 | B6: =IFERROR(3日!B58,"") -> 32 | C6: =IFERROR(3日!F58,"") -> 318 | D6: =IFERROR(3日!J58,"") -> 10.062893 | E6: =IFERROR(3日!G65,"") -> 7 | F6: =IFERROR(3日!K65,"") -> 14 | G6: =IFERROR(3日!P65,"") -> 113 | H6: =IFERROR(3日!T65,"") -> 156 | I6: =IFERROR(3日!Y65,"") -> 5 | J6: =IFERROR(3日!Y68,"") -> 15
A7: 4日 | B7: =IFERROR(4日!B58,"") -> 21 | C7: =IFERROR(4日!F58,"") -> 360 | D7: =IFERROR(4日!J58,"") -> 5.8333333 | E7: =IFERROR(4日!G65,"") -> 5 | F7: =IFERROR(4日!K65,"") -> 19 | G7: =IFERROR(4日!P65,"") -> 180 | H7: =IFERROR(4日!T65,"") -> 245 | I7: =IFERROR(4日!Y65,"") -> 8 | J7: =IFERROR(4日!Y68,"") -> 23
A8: 5日 | B8: =IFERROR(5日!B58,"") -> 20 | C8: =IFERROR(5日!F58,"") -> 257 | D8: =IFERROR(5日!J58,"") -> 7.7821012 | E8: =IFERROR(5日!G65,"") -> 5 | F8: =IFERROR(5日!K65,"") -> 24 | G8: =IFERROR(5日!P65,"") -> 171 | H8: =IFERROR(5日!T65,"") -> 251 | I8: =IFERROR(5日!Y65,"") -> 11 | J8: =IFERROR(5日!Y68,"") -> 34
A9: 6日 | B9: =IFERROR(6日!B58,"") -> 11 | C9: =IFERROR(6日!F58,"") -> 286 | D9: =IFERROR(6日!J58,"") -> 3.8461538 | E9: =IFERROR(6日!G65,"") -> 9 | F9: =IFERROR(6日!K65,"") -> 33 | G9: =IFERROR(6日!P65,"") -> 110 | H9: =IFERROR(6日!T65,"") -> 172 | I9: =IFERROR(6日!Y65,"") -> 15 | J9: =IFERROR(6日!Y68,"") -> 49
A10: 7日 | B10: =IFERROR(7日!B58,"") -> 11 | C10: =IFERROR(7日!F58,"") -> 273 | D10: =IFERROR(7日!J58,"") -> 4.029304 | E10: =IFERROR(7日!G65,"") -> 7 | F10: =IFERROR(7日!K65,"") -> 40 | G10: =IFERROR(7日!P65,"") -> 106 | H10: =IFERROR(7日!T65,"") -> 158 | I10: =IFERROR(7日!Y65,"") -> 9 | J10: =IFERROR(7日!Y68,"") -> 58
A11: 8日 | B11: =IFERROR(8日!B58,"") -> 23 | C11: =IFERROR(8日!F58,"") -> 256 | D11: =IFERROR(8日!J58,"") -> 8.984375 | E11: =IFERROR(8日!G65,"") -> 5 | F11: =IFERROR(8日!K65,"") -> 45 | G11: =IFERROR(8日!P65,"") -> 110 | H11: =IFERROR(8日!T65,"") -> 135 | I11: =IFERROR(8日!Y65,"") -> 16 | J11: =IFERROR(8日!Y68,"") -> 74
A12: 9日 | B12: =IFERROR(9日!B58,"") -> 35 | C12: =IFERROR(9日!F58,"") -> 199 | D12: =IFERROR(9日!J58,"") -> 17.58794 | E12: =IFERROR(9日!G65,"") -> 7 | F12: =IFERROR(9日!K65,"") -> 52 | G12: =IFERROR(9日!P65,"") -> 103 | H12: =IFERROR(9日!T65,"") -> 121 | I12: =IFERROR(9日!Y65,"") -> 14 | J12: =IFERROR(9日!Y68,"") -> 88
A13: 10日 | B13: =IFERROR(10日!B58,"") -> 19 | C13: =IFERROR(10日!F58,"") -> 160 | D13: =IFERROR(10日!J58,"") -> 11.875 | E13: =IFERROR(10日!G65,"") -> 5 | F13: =IFERROR(10日!K65,"") -> 57 | G13: =IFERROR(10日!P65,"") -> 77 | H13: =IFERROR(10日!T65,"") -> 117 | I13: =IFERROR(10日!Y65,"") -> 17 | J13: =IFERROR(10日!Y68,"") -> 105
A14: 11日 | B14: =IFERROR(11日!B58,"") -> 22 | C14: =IFERROR(11日!F58,"") -> 251 | D14: =IFERROR(11日!J58,"") -> 8.7649402 | E14: =IFERROR(11日!G65,"") -> 4 | F14: =IFERROR(11日!K65,"") -> 61 | G14: =IFERROR(11日!P65,"") -> 113 | H14: =IFERROR(11日!T65,"") -> 171 | I14: =IFERROR(11日!Y65,"") -> 11 | J14: =IFERROR(11日!Y68,"") -> 116
A15: 12日 | B15: =IFERROR(12日!B58,"") -> 12 | C15: =IFERROR(12日!F58,"") -> 285 | D15: =IFERROR(12日!J58,"") -> 4.2105263 | E15: =IFERROR(12日!G65,"") -> 6 | F15: =IFERROR(12日!K65,"") -> 67 | G15: =IFERROR(12日!P65,"") -> 109 | H15: =IFERROR(12日!T65,"") -> 156 | I15: =IFERROR(12日!Y65,"") -> 7 | J15: =IFERROR(12日!Y68,"") -> 123
A16: 13日 | B16: =IFERROR(13日!B58,"") -> 24 | C16: =IFERROR(13日!F58,"") -> 238 | D16: =IFERROR(13日!J58,"") -> 10.084034 | E16: =IFERROR(13日!G65,"") -> 7 | F16: =IFERROR(13日!K65,"") -> 74 | G16: =IFERROR(13日!P65,"") -> 118 | H16: =IFERROR(13日!T65,"") -> 147 | I16: =IFERROR(13日!Y65,"") -> 11 | J16: =IFERROR(13日!Y68,"") -> 134
A17: 14日 | B17: =IFERROR(14日!B58,"") -> 2 | C17: =IFERROR(14日!F58,"") -> 278 | D17: =IFERROR(14日!J58,"") -> 0.71942446 | E17: =IFERROR(14日!G65,"") -> 8 | F17: =IFERROR(14日!K65,"") -> 82 | G17: =IFERROR(14日!P65,"") -> 83 | H17: =IFERROR(14日!T65,"") -> 107 | I17: =IFERROR(14日!Y65,"") -> 10 | J17: =IFERROR(14日!Y68,"") -> 144
A18: 15日 | B18: =IFERROR(15日!B58,"") -> 8 | C18: =IFERROR(15日!F58,"") -> 260 | D18: =IFERROR(15日!J58,"") -> 3.0769231 | E18: =IFERROR(15日!G65,"") -> 8 | F18: =IFERROR(15日!K65,"") -> 90 | G18: =IFERROR(15日!P65,"") -> 89 | H18: =IFERROR(15日!T65,"") -> 109 | I18: =IFERROR(15日!Y65,"") -> 7 | J18: =IFERROR(15日!Y68,"") -> 151
A19: 16日 | B19: =IFERROR(16日!B58,"") -> 4 | C19: =IFERROR(16日!F58,"") -> 274 | D19: =IFERROR(16日!J58,"") -> 1.459854 | E19: =IFERROR(16日!G65,"") -> 9 | F19: =IFERROR(16日!K65,"") -> 99 | G19: =IFERROR(16日!P65,"") -> 118 | H19: =IFERROR(16日!T65,"") -> 149 | I19: =IFERROR(16日!Y65,"") -> 10 | J19: =IFERROR(16日!Y68,"") -> 161
A20: 17日 | B20: =IFERROR(17日!B58,"") -> 3 | C20: =IFERROR(17日!F58,"") -> 208 | D20: =IFERROR(17日!J58,"") -> 1.4423077 | E20: =IFERROR(17日!G65,"") -> 8 | F20: =IFERROR(17日!K65,"") -> 107 | G20: =IFERROR(17日!P65,"") -> 65 | H20: =IFERROR(17日!T65,"") -> 77 | I20: =IFERROR(17日!Y65,"") -> 7 | J20: =IFERROR(17日!Y68,"") -> 168
A21: 18日 | B21: =IFERROR(18日!B58,"") -> 4 | C21: =IFERROR(18日!F58,"") -> 196 | D21: =IFERROR(18日!J58,"") -> 2.0408163 | E21: =IFERROR(18日!G65,"") -> 5 | F21: =IFERROR(18日!K65,"") -> 112 | G21: =IFERROR(18日!P65,"") -> 63 | H21: =IFERROR(18日!T65,"") -> 83 | I21: =IFERROR(18日!Y65,"") -> 11 | J21: =IFERROR(18日!Y68,"") -> 179
A22: 19日 | B22: =IFERROR(19日!B58,"") -> 10 | C22: =IFERROR(19日!F58,"") -> 64 | D22: =IFERROR(19日!J58,"") -> 15.625 | E22: =IFERROR(19日!G65,"") -> 6 | F22: =IFERROR(19日!K65,"") -> 118 | G22: =IFERROR(19日!P65,"") -> 73 | H22: =IFERROR(19日!T65,"") -> 100 | I22: =IFERROR(19日!Y65,"") -> 7 | J22: =IFERROR(19日!Y68,"") -> 186
A23: 20日 | B23: =IFERROR(20日!B58,"") -> 12 | C23: =IFERROR(20日!F58,"") -> 231 | D23: =IFERROR(20日!J58,"") -> 5.1948052 | E23: =IFERROR(20日!G65,"") -> 4 | F23: =IFERROR(20日!K65,"") -> 122 | G23: =IFERROR(20日!P65,"") -> 60 | H23: =IFERROR(20日!T65,"") -> 65 | I23: =IFERROR(20日!Y65,"") -> 6 | J23: =IFERROR(20日!Y68,"") -> 192
A24: 21日 | B24: =IFERROR(21日!B58,"") -> 5 | C24: =IFERROR(21日!F58,"") -> 292 | D24: =IFERROR(21日!J58,"") -> 1.7123288 | E24: =IFERROR(21日!G65,"") -> 0 | F24: =IFERROR(21日!K65,"") -> 122 | G24: =IFERROR(21日!P65,"") -> 71 | H24: =IFERROR(21日!T65,"") -> 92 | I24: =IFERROR(21日!Y65,"") -> 7 | J24: =IFERROR(21日!Y68,"") -> 199
A25: 22日 | B25: =IFERROR(22日!B58,"") -> 4 | C25: =IFERROR(22日!F58,"") -> 297 | D25: =IFERROR(22日!J58,"") -> 1.3468013 | E25: =IFERROR(22日!G65,"") -> 8 | F25: =IFERROR(22日!K65,"") -> 130 | G25: =IFERROR(22日!P65,"") -> 69 | H25: =IFERROR(22日!T65,"") -> 83 | I25: =IFERROR(22日!Y65,"") -> 11 | J25: =IFERROR(22日!Y68,"") -> 210
A26: 23日 | B26: =IFERROR(23日!B58,"") -> 7 | C26: =IFERROR(23日!F58,"") -> 339 | D26: =IFERROR(23日!J58,"") -> 2.0648968 | E26: =IFERROR(23日!G65,"") -> 4 | F26: =IFERROR(23日!K65,"") -> 134 | G26: =IFERROR(23日!P65,"") -> 62 | H26: =IFERROR(23日!T65,"") -> 96 | I26: =IFERROR(23日!Y65,"") -> 10 | J26: =IFERROR(23日!Y68,"") -> 220
A27: 24日 | B27: =IFERROR(24日!B58,"") -> 19 | C27: =IFERROR(24日!F58,"") -> 270 | D27: =IFERROR(24日!J58,"") -> 7.037037 | E27: =IFERROR(24日!G65,"") -> 6 | F27: =IFERROR(24日!K65,"") -> 140 | G27: =IFERROR(24日!P65,"") -> 104 | H27: =IFERROR(24日!T65,"") -> 164 | I27: =IFERROR(24日!Y65,"") -> 9 | J27: =IFERROR(24日!Y68,"") -> 229
A28: 25日 | B28: =IFERROR(25日!B58,"") -> 4 | C28: =IFERROR(25日!F58,"") -> 209 | D28: =IFERROR(25日!J58,"") -> 1.9138756 | E28: =IFERROR(25日!G65,"") -> 6 | F28: =IFERROR(25日!K65,"") -> 146 | G28: =IFERROR(25日!P65,"") -> 99 | H28: =IFERROR(25日!T65,"") -> 169 | I28: =IFERROR(25日!Y65,"") -> 9 | J28: =IFERROR(25日!Y68,"") -> 238
A29: 26日 | B29: =IFERROR(26日!B58,"") -> 1 | C29: =IFERROR(26日!F58,"") -> 80 | D29: =IFERROR(26日!J58,"") -> 1.25 | E29: =IFERROR(26日!G65,"") -> 7 | F29: =IFERROR(26日!K65,"") -> 153 | G29: =IFERROR(26日!P65,"") -> 96 | H29: =IFERROR(26日!T65,"") -> 127 | I29: =IFERROR(26日!Y65,"") -> 10 | J29: =IFERROR(26日!Y68,"") -> 248
A30: 27日 | B30: =IFERROR(27日!B58,"") -> 6 | C30: =IFERROR(27日!F58,"") -> 57 | D30: =IFERROR(27日!J58,"") -> 10.526316 | E30: =IFERROR(27日!G65,"") -> 7 | F30: =IFERROR(27日!K65,"") -> 160 | G30: =IFERROR(27日!P65,"") -> 72 | H30: =IFERROR(27日!T65,"") -> 95 | I30: =IFERROR(27日!Y65,"") -> 11 | J30: =IFERROR(27日!Y68,"") -> 259
A31: 28日 | B31: =IFERROR(28日!B58,"") -> 8 | C31: =IFERROR(28日!F58,"") -> 255 | D31: =IFERROR(28日!J58,"") -> 3.1372549 | E31: =IFERROR(28日!G65,"") -> 2 | F31: =IFERROR(28日!K65,"") -> 162 | G31: =IFERROR(28日!P65,"") -> 76 | H31: =IFERROR(28日!T65,"") -> 104 | I31: =IFERROR(28日!Y65,"") -> 3 | J31: =IFERROR(28日!Y68,"") -> 262
A32: 29日 | B32: =IFERROR(29日!B58,"") -> 14 | C32: =IFERROR(29日!F58,"") -> 181 | D32: =IFERROR(29日!J58,"") -> 7.7348066 | E32: =IFERROR(29日!G65,"") -> 6 | F32: =IFERROR(29日!K65,"") -> 168 | G32: =IFERROR(29日!P65,"") -> 67 | H32: =IFERROR(29日!T65,"") -> 92 | I32: =IFERROR(29日!Y65,"") -> 11 | J32: =IFERROR(29日!Y68,"") -> 273
A33: 30日 | B33: =IFERROR(30日!B58,"") -> 11 | C33: =IFERROR(30日!F58,"") -> 173 | D33: =IFERROR(30日!J58,"") -> 6.3583815 | E33: =IFERROR(30日!G65,"") -> 0 | F33: =IFERROR(30日!K65,"") -> 168 | G33: =IFERROR(30日!P65,"") -> 78 | H33: =IFERROR(30日!T65,"") -> 82 | I33: =IFERROR(30日!Y65,"") -> 4 | J33: =IFERROR(30日!Y68,"") -> 277
A34: 31日 | B34: =IFERROR(31日!B58,"") -> 9 | C34: =IFERROR(31日!F58,"") -> 244 | D34: =IFERROR(31日!J58,"") -> 3.6885246 | E34: =IFERROR(31日!G65,"") -> 7 | F34: =IFERROR(31日!K65,"") -> 175 | G34: =IFERROR(31日!P65,"") -> 76 | H34: =IFERROR(31日!T65,"") -> 91 | I34: =IFERROR(31日!Y65,"") -> 9 | J34: =IFERROR(31日!Y68,"") -> 286
A35: 合計/平均 | B35: =SUM(B4:B34) -> 429 | C35: =SUM(C4:C34) -> 7203 | D35: =IFERROR(AVERAGE(D4:D34),"") -> 6.5330605 | E35: =SUM(E4:E34) -> 175 | G35: =SUM(G4:G34) -> 2939 | H35: =SUM(H4:H34) -> 3960 | I35: =SUM(I4:I34) -> 286

Sheet 生産高_月次
A1: （４）生産高 月次集計
A2: データ出典: 各日シート（1日～31日）へのリンク数式。数値は元シートの値がそのまま反映されます。
A3: 日 | B3: 既設カッター 実績(t) | C3: 既設カッター 計画(t) | D3: 既設カッター 増減(t) | E3: 既設カッター 累計実績(t) | F3: ５C/Rワインダー 実績(t) | G3: ５C/Rワインダー 計画(t) | H3: ５C/Rワインダー 増減(t) | I3: ５C/Rワインダー 累計実績(t) | J3: ５C/Rカッター 実績(t) | K3: ５C/Rカッター 計画(t) | L3: ５C/Rカッター 増減(t) | M3: ５C/Rカッター 累計実績(t)
A4: 1日 | B4: =IFERROR(1日!G75,"") -> 0 | C4: =IFERROR(1日!K75,"") -> -0.022556391 | D4: =IFERROR(1日!O75,"") -> 0.022556391 | E4: =IFERROR(1日!S75,"") -> 0 | F4: =IFERROR(1日!G76,"") -> 378.318 | G4: =IFERROR(1日!K76,"") -> 408.82852 | H4: =IFERROR(1日!O76,"") -> -30.510523 | I4: =IFERROR(1日!S76,"") -> 378.318 | J4: =IFERROR(1日!G77,"") -> 120.4 | K4: =IFERROR(1日!K77,"") -> 142.10526 | L4: =IFERROR(1日!O77,"") -> -21.705263 | M4: =IFERROR(1日!S77,"") -> 120.4
A5: 2日 | B5: =IFERROR(2日!G75,"") -> 0 | C5: =IFERROR(2日!K75,"") -> 0 | D5: =IFERROR(2日!O75,"") -> 0 | E5: =IFERROR(2日!S75,"") -> 0 | F5: =IFERROR(2日!G76,"") -> 412.827 | G5: =IFERROR(2日!K76,"") -> 408.82852 | H5: =IFERROR(2日!O76,"") -> 3.9984771 | I5: =IFERROR(2日!S76,"") -> 791.145 | J5: =IFERROR(2日!G77,"") -> 111.2 | K5: =IFERROR(2日!K77,"") -> 142.10526 | L5: =IFERROR(2日!O77,"") -> -30.905263 | M5: =IFERROR(2日!S77,"") -> 231.7
A6: 3日 | B6: =IFERROR(3日!G75,"") -> 23.029 | C6: =IFERROR(3日!K75,"") -> 0 | D6: =IFERROR(3日!O75,"") -> 23.029 | E6: =IFERROR(3日!S75,"") -> 23.029 | F6: =IFERROR(3日!G76,"") -> 383.112 | G6: =IFERROR(3日!K76,"") -> 408.82852 | H6: =IFERROR(3日!O76,"") -> -25.716523 | I6: =IFERROR(3日!S76,"") -> 1174.257 | J6: =IFERROR(3日!G77,"") -> 200.9 | K6: =IFERROR(3日!K77,"") -> 142.10526 | L6: =IFERROR(3日!O77,"") -> 58.794737 | M6: =IFERROR(3日!S77,"") -> 432.7
A7: 4日 | B7: =IFERROR(4日!G75,"") -> 19.95 | C7: =IFERROR(4日!K75,"") -> 110.97744 | D7: =IFERROR(4日!O75,"") -> -91.027444 | E7: =IFERROR(4日!S75,"") -> 42.979 | F7: =IFERROR(4日!G76,"") -> 385.191 | G7: =IFERROR(4日!K76,"") -> 408.82852 | H7: =IFERROR(4日!O76,"") -> -23.637523 | I7: =IFERROR(4日!S76,"") -> 1559.448 | J7: =IFERROR(4日!G77,"") -> 221.1 | K7: =IFERROR(4日!K77,"") -> 142.10526 | L7: =IFERROR(4日!O77,"") -> 78.994737 | M7: =IFERROR(4日!S77,"") -> 653.8
